facturasieli  | Watching for file changes with StatReloader
facturasieli  | [28/May/2024 12:39:53] "GET / HTTP/1.1" 302 0
facturasieli  | [28/May/2024 12:39:53] "GET /en/ HTTP/1.1" 302 0
facturasieli  | [28/May/2024 12:39:53] "GET /en/custom_login/ HTTP/1.1" 200 2137
facturasieli  | Not Found: /favicon.ico
facturasieli  | [28/May/2024 12:39:53] "GET /favicon.ico HTTP/1.1" 404 2107
facturasieli  | Watching for file changes with StatReloader
facturasieli  | [28/May/2024 14:41:31] "GET / HTTP/1.1" 302 0
facturasieli  | [28/May/2024 14:41:31] "GET /en/ HTTP/1.1" 302 0
facturasieli  | [28/May/2024 14:41:31] "GET /en/custom_login/ HTTP/1.1" 200 2137
facturasieli  | [28/May/2024 14:41:33] "GET /en/register/ HTTP/1.1" 200 2895
facturasieli  | [28/May/2024 14:41:58] "POST /en/register/ HTTP/1.1" 200 3033
facturasieli  | [28/May/2024 14:42:16] "POST /en/register/ HTTP/1.1" 302 0
facturasieli  | [28/May/2024 14:42:16] "GET /en/welcome/ HTTP/1.1" 200 1419
facturasieli  | [28/May/2024 14:42:20] "GET /en/custom_login/ HTTP/1.1" 200 2137
facturasieli  | [28/May/2024 14:42:29] "POST /en/custom_login/ HTTP/1.1" 302 0
facturasieli  | [28/May/2024 14:42:29] "GET /en/ HTTP/1.1" 200 2200
facturasieli  | [28/May/2024 14:42:29] "GET /media/default_avatar.jpg HTTP/1.1" 302 0
facturasieli  | [28/May/2024 14:42:29] "GET /en/media/default_avatar.jpg HTTP/1.1" 200 2740
facturasieli  | [28/May/2024 14:42:33] "GET /en/ HTTP/1.1" 200 2200
facturasieli  | [28/May/2024 14:42:33] "GET /media/default_avatar.jpg HTTP/1.1" 302 0
facturasieli  | [28/May/2024 14:42:34] "GET /en/public_profile/1/ HTTP/1.1" 200 2224
facturasieli  | [28/May/2024 14:42:34] "GET /media/default_avatar.jpg HTTP/1.1" 302 0
facturasieli  | [28/May/2024 14:42:42] "GET /en/ HTTP/1.1" 200 2200
facturasieli  | [28/May/2024 14:42:42] "GET /media/default_avatar.jpg HTTP/1.1" 302 0
facturasieli  | /FacturaSieli/facturasieli/urls.py changed, reloading.
facturasieli  | Performing system checks...
facturasieli  | 
facturasieli  | System check identified no issues (0 silenced).
facturasieli  | May 28, 2024 - 14:41:05
facturasieli  | Django version 5.0.6, using settings 'config.settings'
facturasieli  | Starting development server at http://0.0.0.0:8000/
facturasieli  | Quit the server with CONTROL-C.
facturasieli  | 
facturasieli  | Watching for file changes with StatReloader
facturasieli  | [28/May/2024 16:07:43] "GET /en/ HTTP/1.1" 200 2356
facturasieli  | [28/May/2024 16:07:43] "GET /media/default_avatar.jpg HTTP/1.1" 302 0
facturasieli  | [28/May/2024 16:07:44] "GET /en/media/default_avatar.jpg HTTP/1.1" 304 0
facturasieli  | [28/May/2024 16:07:44] "GET /en/public_profile/1/ HTTP/1.1" 200 2380
facturasieli  | [28/May/2024 16:07:45] "GET /media/default_avatar.jpg HTTP/1.1" 302 0
facturasieli  | Not Found: /en/service/2/
facturasieli  | [28/May/2024 16:07:46] "GET /en/service/2/ HTTP/1.1" 404 4884
facturasieli  | Watching for file changes with StatReloader
facturasieli  | [28/May/2024 21:44:07] "GET / HTTP/1.1" 302 0
facturasieli  | [28/May/2024 21:44:07] "GET /en/ HTTP/1.1" 200 2356
facturasieli  | [28/May/2024 21:44:07] "GET /media/default_avatar.jpg HTTP/1.1" 302 0
facturasieli  | [28/May/2024 21:44:07] "GET /en/media/default_avatar.jpg HTTP/1.1" 304 0
facturasieli  | Not Found: /favicon.ico
facturasieli  | [28/May/2024 21:44:07] "GET /favicon.ico HTTP/1.1" 404 2107
facturasieli  | /FacturaSieli/facturasieli/urls.py changed, reloading.
facturasieli  | Performing system checks...
facturasieli  | 
facturasieli  | System check identified no issues (0 silenced).
facturasieli  | May 28, 2024 - 21:44:00
facturasieli  | Django version 5.0.6, using settings 'config.settings'
facturasieli  | Starting development server at http://0.0.0.0:8000/
facturasieli  | Quit the server with CONTROL-C.
facturasieli  | 
facturasieli  | Watching for file changes with StatReloader
facturasieli  | Exception in thread django-main-thread:
facturasieli  | Traceback (most recent call last):
facturasieli  |   File "/usr/lib/python3.11/threading.py", line 1038, in _bootstrap_inner
facturasieli  |     self.run()
facturasieli  |   File "/usr/lib/python3.11/threading.py", line 975, in run
facturasieli  |     self._target(*self._args, **self._kwargs)
facturasieli  |   File "//.venv/lib/python3.11/site-packages/django/utils/autoreload.py", line 64, in wrapper
facturasieli  |     fn(*args, **kwargs)
facturasieli  |   File "//.venv/lib/python3.11/site-packages/django/core/management/commands/runserver.py", line 133, in inner_run
facturasieli  |     self.check(display_num_errors=True)
facturasieli  |   File "//.venv/lib/python3.11/site-packages/django/core/management/base.py", line 486, in check
facturasieli  |     all_issues = checks.run_checks(
facturasieli  |                  ^^^^^^^^^^^^^^^^^^
facturasieli  |   File "//.venv/lib/python3.11/site-packages/django/core/checks/registry.py", line 88, in run_checks
facturasieli  |     new_errors = check(app_configs=app_configs, databases=databases)
facturasieli  |                  ^^^^^^^^^^^^^^^^^^^^^^^^^^^^^^^^^^^^^^^^^^^^^^^^^^^
facturasieli  |   File "//.venv/lib/python3.11/site-packages/django/core/checks/urls.py", line 42, in check_url_namespaces_unique
facturasieli  |     all_namespaces = _load_all_namespaces(resolver)
facturasieli  |                      ^^^^^^^^^^^^^^^^^^^^^^^^^^^^^^
facturasieli  |   File "//.venv/lib/python3.11/site-packages/django/core/checks/urls.py", line 61, in _load_all_namespaces
facturasieli  |     url_patterns = getattr(resolver, "url_patterns", [])
facturasieli  |                    ^^^^^^^^^^^^^^^^^^^^^^^^^^^^^^^^^^^^^
facturasieli  |   File "//.venv/lib/python3.11/site-packages/django/utils/functional.py", line 47, in __get__
facturasieli  |     res = instance.__dict__[self.name] = self.func(instance)
facturasieli  |                                          ^^^^^^^^^^^^^^^^^^^
facturasieli  |   File "//.venv/lib/python3.11/site-packages/django/urls/resolvers.py", line 738, in url_patterns
facturasieli  |     patterns = getattr(self.urlconf_module, "urlpatterns", self.urlconf_module)
facturasieli  |                        ^^^^^^^^^^^^^^^^^^^
facturasieli  |   File "//.venv/lib/python3.11/site-packages/django/utils/functional.py", line 47, in __get__
facturasieli  |     res = instance.__dict__[self.name] = self.func(instance)
facturasieli  |                                          ^^^^^^^^^^^^^^^^^^^
facturasieli  |   File "//.venv/lib/python3.11/site-packages/django/urls/resolvers.py", line 731, in urlconf_module
facturasieli  |     return import_module(self.urlconf_name)
facturasieli  |            ^^^^^^^^^^^^^^^^^^^^^^^^^^^^^^^^
facturasieli  |   File "/usr/lib/python3.11/importlib/__init__.py", line 126, in import_module
facturasieli  |     return _bootstrap._gcd_import(name[level:], package, level)
facturasieli  |            ^^^^^^^^^^^^^^^^^^^^^^^^^^^^^^^^^^^^^^^^^^^^^^^^^^^^
facturasieli  |   File "<frozen importlib._bootstrap>", line 1206, in _gcd_import
facturasieli  |   File "<frozen importlib._bootstrap>", line 1178, in _find_and_load
facturasieli  |   File "<frozen importlib._bootstrap>", line 1149, in _find_and_load_unlocked
facturasieli  |   File "<frozen importlib._bootstrap>", line 690, in _load_unlocked
facturasieli  |   File "<frozen importlib._bootstrap_external>", line 940, in exec_module
facturasieli  |   File "<frozen importlib._bootstrap>", line 241, in _call_with_frames_removed
facturasieli  |   File "/FacturaSieli/config/urls.py", line 28, in <module>
facturasieli  |     path('', include('facturasieli.urls')),
facturasieli  |              ^^^^^^^^^^^^^^^^^^^^^^^^^^^^
facturasieli  |   File "//.venv/lib/python3.11/site-packages/django/urls/conf.py", line 39, in include
facturasieli  |     urlconf_module = import_module(urlconf_module)
facturasieli  |                      ^^^^^^^^^^^^^^^^^^^^^^^^^^^^^
facturasieli  |   File "/usr/lib/python3.11/importlib/__init__.py", line 126, in import_module
facturasieli  |     return _bootstrap._gcd_import(name[level:], package, level)
facturasieli  |            ^^^^^^^^^^^^^^^^^^^^^^^^^^^^^^^^^^^^^^^^^^^^^^^^^^^^
facturasieli  |   File "<frozen importlib._bootstrap>", line 1206, in _gcd_import
facturasieli  |   File "<frozen importlib._bootstrap>", line 1178, in _find_and_load
facturasieli  |   File "<frozen importlib._bootstrap>", line 1149, in _find_and_load_unlocked
facturasieli  |   File "<frozen importlib._bootstrap>", line 690, in _load_unlocked
facturasieli  |   File "<frozen importlib._bootstrap_external>", line 940, in exec_module
facturasieli  |   File "<frozen importlib._bootstrap>", line 241, in _call_with_frames_removed
facturasieli  |   File "/FacturaSieli/facturasieli/urls.py", line 6, in <module>
facturasieli  |     from facturasieli.views.invoice_view import invoice_view, invoice_success
facturasieli  | ImportError: cannot import name 'invoice_success' from 'facturasieli.views.invoice_view' (/FacturaSieli/facturasieli/views/invoice_view.py)
facturasieli  | /FacturaSieli/facturasieli/views/invoice_view.py changed, reloading.
facturasieli  | Performing system checks...
facturasieli  | 
facturasieli  | Watching for file changes with StatReloader
facturasieli  | /FacturaSieli/config/settings.py changed, reloading.
facturasieli  | Performing system checks...
facturasieli  | 
facturasieli  | System check identified no issues (0 silenced).
facturasieli  | May 28, 2024 - 22:38:58
facturasieli  | Django version 5.0.6, using settings 'config.settings'
facturasieli  | Starting development server at http://0.0.0.0:8000/
facturasieli  | Quit the server with CONTROL-C.
facturasieli  | 
facturasieli  | Watching for file changes with StatReloader
facturasieli  | Exception in thread django-main-thread:
facturasieli  | Traceback (most recent call last):
facturasieli  |   File "/usr/lib/python3.11/threading.py", line 1038, in _bootstrap_inner
facturasieli  |     self.run()
facturasieli  |   File "/usr/lib/python3.11/threading.py", line 975, in run
facturasieli  |     self._target(*self._args, **self._kwargs)
facturasieli  |   File "//.venv/lib/python3.11/site-packages/django/utils/autoreload.py", line 64, in wrapper
facturasieli  |     fn(*args, **kwargs)
facturasieli  |   File "//.venv/lib/python3.11/site-packages/django/core/management/commands/runserver.py", line 125, in inner_run
facturasieli  |     autoreload.raise_last_exception()
facturasieli  |   File "//.venv/lib/python3.11/site-packages/django/utils/autoreload.py", line 87, in raise_last_exception
facturasieli  |     raise _exception[1]
facturasieli  |   File "//.venv/lib/python3.11/site-packages/django/core/management/__init__.py", line 394, in execute
facturasieli  |     autoreload.check_errors(django.setup)()
facturasieli  |   File "//.venv/lib/python3.11/site-packages/django/utils/autoreload.py", line 64, in wrapper
facturasieli  |     fn(*args, **kwargs)
facturasieli  |   File "//.venv/lib/python3.11/site-packages/django/__init__.py", line 24, in setup
facturasieli  |     apps.populate(settings.INSTALLED_APPS)
facturasieli  |   File "//.venv/lib/python3.11/site-packages/django/apps/registry.py", line 93, in populate
facturasieli  |     raise ImproperlyConfigured(
facturasieli  | django.core.exceptions.ImproperlyConfigured: Application labels aren't unique, duplicates: facturasieli
facturasieli  | Watching for file changes with StatReloader
facturasieli  | [28/May/2024 22:45:01] "GET / HTTP/1.1" 302 0
facturasieli  | [28/May/2024 22:45:01] "GET /en/ HTTP/1.1" 200 2356
facturasieli  | [28/May/2024 22:45:01] "GET /media/default_avatar.jpg HTTP/1.1" 302 0
facturasieli  | [28/May/2024 22:45:03] "GET /invoice/ HTTP/1.1" 302 0
facturasieli  | [28/May/2024 22:45:04] "GET /en/invoice/ HTTP/1.1" 200 2404
facturasieli  | /FacturaSieli/facturasieli/admin.py changed, reloading.
facturasieli  | Performing system checks...
facturasieli  | 
facturasieli  | System check identified no issues (0 silenced).
facturasieli  | May 28, 2024 - 22:44:54
facturasieli  | Django version 5.0.6, using settings 'config.settings'
facturasieli  | Starting development server at http://0.0.0.0:8000/
facturasieli  | Quit the server with CONTROL-C.
facturasieli  | 
facturasieli  | Watching for file changes with StatReloader
facturasieli  | Watching for file changes with StatReloader
facturasieli  | [29/May/2024 10:39:03] "GET / HTTP/1.1" 302 0
facturasieli  | [29/May/2024 10:39:03] "GET /en/ HTTP/1.1" 200 2356
facturasieli  | [29/May/2024 10:39:03] "GET /media/default_avatar.jpg HTTP/1.1" 302 0
facturasieli  | [29/May/2024 10:39:03] "GET /en/media/default_avatar.jpg HTTP/1.1" 304 0
facturasieli  | Not Found: /favicon.ico
facturasieli  | [29/May/2024 10:39:03] "GET /favicon.ico HTTP/1.1" 404 2107
facturasieli  | /FacturaSieli/facturasieli/admin.py changed, reloading.
facturasieli  | Performing system checks...
facturasieli  | 
facturasieli  | System check identified no issues (0 silenced).
facturasieli  | May 29, 2024 - 10:37:29
facturasieli  | Django version 5.0.6, using settings 'config.settings'
facturasieli  | Starting development server at http://0.0.0.0:8000/
facturasieli  | Quit the server with CONTROL-C.
facturasieli  | 
facturasieli  | Watching for file changes with StatReloader
facturasieli  | /FacturaSieli/facturasieli/models/Address.py changed, reloading.
facturasieli  | Performing system checks...
facturasieli  | 
facturasieli  | System check identified no issues (0 silenced).
facturasieli  | May 29, 2024 - 10:50:00
facturasieli  | Django version 5.0.6, using settings 'config.settings'
facturasieli  | Starting development server at http://0.0.0.0:8000/
facturasieli  | Quit the server with CONTROL-C.
facturasieli  | 
facturasieli  | Watching for file changes with StatReloader
facturasieli  | /FacturaSieli/facturasieli/admin.py changed, reloading.
facturasieli  | Performing system checks...
facturasieli  | 
facturasieli  | System check identified no issues (0 silenced).
facturasieli  | May 29, 2024 - 10:51:08
facturasieli  | Django version 5.0.6, using settings 'config.settings'
facturasieli  | Starting development server at http://0.0.0.0:8000/
facturasieli  | Quit the server with CONTROL-C.
facturasieli  | 
facturasieli  | Watching for file changes with StatReloader
facturasieli  | /FacturaSieli/facturasieli/urls.py changed, reloading.
facturasieli  | Performing system checks...
facturasieli  | 
facturasieli  | System check identified no issues (0 silenced).
facturasieli  | May 29, 2024 - 10:53:02
facturasieli  | Django version 5.0.6, using settings 'config.settings'
facturasieli  | Starting development server at http://0.0.0.0:8000/
facturasieli  | Quit the server with CONTROL-C.
facturasieli  | 
facturasieli  | Watching for file changes with StatReloader
facturasieli  | /FacturaSieli/facturasieli/urls.py changed, reloading.
facturasieli  | Performing system checks...
facturasieli  | 
facturasieli  | System check identified no issues (0 silenced).
facturasieli  | May 29, 2024 - 10:53:18
facturasieli  | Django version 5.0.6, using settings 'config.settings'
facturasieli  | Starting development server at http://0.0.0.0:8000/
facturasieli  | Quit the server with CONTROL-C.
facturasieli  | 
facturasieli  | Watching for file changes with StatReloader
facturasieli  | /FacturaSieli/facturasieli/admin.py changed, reloading.
facturasieli  | Performing system checks...
facturasieli  | 
facturasieli  | System check identified no issues (0 silenced).
facturasieli  | May 29, 2024 - 10:53:55
facturasieli  | Django version 5.0.6, using settings 'config.settings'
facturasieli  | Starting development server at http://0.0.0.0:8000/
facturasieli  | Quit the server with CONTROL-C.
facturasieli  | 
facturasieli  | Watching for file changes with StatReloader
facturasieli  | Internal Server Error: /en/
facturasieli  | Traceback (most recent call last):
facturasieli  |   File "//.venv/lib/python3.11/site-packages/django/db/backends/utils.py", line 105, in _execute
facturasieli  |     return self.cursor.execute(sql, params)
facturasieli  |            ^^^^^^^^^^^^^^^^^^^^^^^^^^^^^^^^
facturasieli  |   File "//.venv/lib/python3.11/site-packages/django/db/backends/sqlite3/base.py", line 329, in execute
facturasieli  |     return super().execute(query, params)
facturasieli  |            ^^^^^^^^^^^^^^^^^^^^^^^^^^^^^^
facturasieli  | sqlite3.OperationalError: no such column: facturasieli_profile.last_login
facturasieli  | 
facturasieli  | The above exception was the direct cause of the following exception:
facturasieli  | 
facturasieli  | Traceback (most recent call last):
facturasieli  |   File "//.venv/lib/python3.11/site-packages/django/core/handlers/exception.py", line 55, in inner
facturasieli  |     response = get_response(request)
facturasieli  |                ^^^^^^^^^^^^^^^^^^^^^
facturasieli  |   File "/FacturaSieli/facturasieli/middleware.py", line 20, in __call__
facturasieli  |     profile = Profile.objects.get(email=request.user)
facturasieli  |               ^^^^^^^^^^^^^^^^^^^^^^^^^^^^^^^^^^^^^^^
facturasieli  |   File "//.venv/lib/python3.11/site-packages/django/db/models/manager.py", line 87, in manager_method
facturasieli  |     return getattr(self.get_queryset(), name)(*args, **kwargs)
facturasieli  |            ^^^^^^^^^^^^^^^^^^^^^^^^^^^^^^^^^^^^^^^^^^^^^^^^^^^
facturasieli  |   File "//.venv/lib/python3.11/site-packages/django/db/models/query.py", line 645, in get
facturasieli  |     num = len(clone)
facturasieli  |           ^^^^^^^^^^
facturasieli  |   File "//.venv/lib/python3.11/site-packages/django/db/models/query.py", line 382, in __len__
facturasieli  |     self._fetch_all()
facturasieli  |   File "//.venv/lib/python3.11/site-packages/django/db/models/query.py", line 1928, in _fetch_all
facturasieli  |     self._result_cache = list(self._iterable_class(self))
facturasieli  |                          ^^^^^^^^^^^^^^^^^^^^^^^^^^^^^^^^
facturasieli  |   File "//.venv/lib/python3.11/site-packages/django/db/models/query.py", line 91, in __iter__
facturasieli  |     results = compiler.execute_sql(
facturasieli  |               ^^^^^^^^^^^^^^^^^^^^^
facturasieli  |   File "//.venv/lib/python3.11/site-packages/django/db/models/sql/compiler.py", line 1562, in execute_sql
facturasieli  |     cursor.execute(sql, params)
facturasieli  |   File "//.venv/lib/python3.11/site-packages/django/db/backends/utils.py", line 122, in execute
facturasieli  |     return super().execute(sql, params)
facturasieli  |            ^^^^^^^^^^^^^^^^^^^^^^^^^^^^
facturasieli  |   File "//.venv/lib/python3.11/site-packages/django/db/backends/utils.py", line 79, in execute
facturasieli  |     return self._execute_with_wrappers(
facturasieli  |            ^^^^^^^^^^^^^^^^^^^^^^^^^^^^
facturasieli  |   File "//.venv/lib/python3.11/site-packages/django/db/backends/utils.py", line 92, in _execute_with_wrappers
facturasieli  |     return executor(sql, params, many, context)
facturasieli  |            ^^^^^^^^^^^^^^^^^^^^^^^^^^^^^^^^^^^^
facturasieli  |   File "//.venv/lib/python3.11/site-packages/django/db/backends/utils.py", line 100, in _execute
facturasieli  |     with self.db.wrap_database_errors:
facturasieli  |   File "//.venv/lib/python3.11/site-packages/django/db/utils.py", line 91, in __exit__
facturasieli  |     raise dj_exc_value.with_traceback(traceback) from exc_value
facturasieli  |   File "//.venv/lib/python3.11/site-packages/django/db/backends/utils.py", line 105, in _execute
facturasieli  |     return self.cursor.execute(sql, params)
facturasieli  |            ^^^^^^^^^^^^^^^^^^^^^^^^^^^^^^^^
facturasieli  |   File "//.venv/lib/python3.11/site-packages/django/db/backends/sqlite3/base.py", line 329, in execute
facturasieli  |     return super().execute(query, params)
facturasieli  |            ^^^^^^^^^^^^^^^^^^^^^^^^^^^^^^
facturasieli  | django.db.utils.OperationalError: no such column: facturasieli_profile.last_login
facturasieli  | [29/May/2024 10:54:04] "GET /en/ HTTP/1.1" 500 122002
facturasieli  | Internal Server Error: /
facturasieli  | Traceback (most recent call last):
facturasieli  |   File "//.venv/lib/python3.11/site-packages/django/db/backends/utils.py", line 105, in _execute
facturasieli  |     return self.cursor.execute(sql, params)
facturasieli  |            ^^^^^^^^^^^^^^^^^^^^^^^^^^^^^^^^
facturasieli  |   File "//.venv/lib/python3.11/site-packages/django/db/backends/sqlite3/base.py", line 329, in execute
facturasieli  |     return super().execute(query, params)
facturasieli  |            ^^^^^^^^^^^^^^^^^^^^^^^^^^^^^^
facturasieli  | sqlite3.OperationalError: no such column: facturasieli_profile.last_login
facturasieli  | 
facturasieli  | The above exception was the direct cause of the following exception:
facturasieli  | 
facturasieli  | Traceback (most recent call last):
facturasieli  |   File "//.venv/lib/python3.11/site-packages/django/core/handlers/exception.py", line 55, in inner
facturasieli  |     response = get_response(request)
facturasieli  |                ^^^^^^^^^^^^^^^^^^^^^
facturasieli  |   File "/FacturaSieli/facturasieli/middleware.py", line 20, in __call__
facturasieli  |     profile = Profile.objects.get(email=request.user)
facturasieli  |               ^^^^^^^^^^^^^^^^^^^^^^^^^^^^^^^^^^^^^^^
facturasieli  |   File "//.venv/lib/python3.11/site-packages/django/db/models/manager.py", line 87, in manager_method
facturasieli  |     return getattr(self.get_queryset(), name)(*args, **kwargs)
facturasieli  |            ^^^^^^^^^^^^^^^^^^^^^^^^^^^^^^^^^^^^^^^^^^^^^^^^^^^
facturasieli  |   File "//.venv/lib/python3.11/site-packages/django/db/models/query.py", line 645, in get
facturasieli  |     num = len(clone)
facturasieli  |           ^^^^^^^^^^
facturasieli  |   File "//.venv/lib/python3.11/site-packages/django/db/models/query.py", line 382, in __len__
facturasieli  |     self._fetch_all()
facturasieli  |   File "//.venv/lib/python3.11/site-packages/django/db/models/query.py", line 1928, in _fetch_all
facturasieli  |     self._result_cache = list(self._iterable_class(self))
facturasieli  |                          ^^^^^^^^^^^^^^^^^^^^^^^^^^^^^^^^
facturasieli  |   File "//.venv/lib/python3.11/site-packages/django/db/models/query.py", line 91, in __iter__
facturasieli  |     results = compiler.execute_sql(
facturasieli  |               ^^^^^^^^^^^^^^^^^^^^^
facturasieli  |   File "//.venv/lib/python3.11/site-packages/django/db/models/sql/compiler.py", line 1562, in execute_sql
facturasieli  |     cursor.execute(sql, params)
facturasieli  |   File "//.venv/lib/python3.11/site-packages/django/db/backends/utils.py", line 122, in execute
facturasieli  |     return super().execute(sql, params)
facturasieli  |            ^^^^^^^^^^^^^^^^^^^^^^^^^^^^
facturasieli  |   File "//.venv/lib/python3.11/site-packages/django/db/backends/utils.py", line 79, in execute
facturasieli  |     return self._execute_with_wrappers(
facturasieli  |            ^^^^^^^^^^^^^^^^^^^^^^^^^^^^
facturasieli  |   File "//.venv/lib/python3.11/site-packages/django/db/backends/utils.py", line 92, in _execute_with_wrappers
facturasieli  |     return executor(sql, params, many, context)
facturasieli  |            ^^^^^^^^^^^^^^^^^^^^^^^^^^^^^^^^^^^^
facturasieli  |   File "//.venv/lib/python3.11/site-packages/django/db/backends/utils.py", line 100, in _execute
facturasieli  |     with self.db.wrap_database_errors:
facturasieli  |   File "//.venv/lib/python3.11/site-packages/django/db/utils.py", line 91, in __exit__
facturasieli  |     raise dj_exc_value.with_traceback(traceback) from exc_value
facturasieli  |   File "//.venv/lib/python3.11/site-packages/django/db/backends/utils.py", line 105, in _execute
facturasieli  |     return self.cursor.execute(sql, params)
facturasieli  |            ^^^^^^^^^^^^^^^^^^^^^^^^^^^^^^^^
facturasieli  |   File "//.venv/lib/python3.11/site-packages/django/db/backends/sqlite3/base.py", line 329, in execute
facturasieli  |     return super().execute(query, params)
facturasieli  |            ^^^^^^^^^^^^^^^^^^^^^^^^^^^^^^
facturasieli  | django.db.utils.OperationalError: no such column: facturasieli_profile.last_login
facturasieli  | [29/May/2024 10:54:08] "GET / HTTP/1.1" 500 122095
facturasieli  | Internal Server Error: /
facturasieli  | Traceback (most recent call last):
facturasieli  |   File "//.venv/lib/python3.11/site-packages/django/db/backends/utils.py", line 105, in _execute
facturasieli  |     return self.cursor.execute(sql, params)
facturasieli  |            ^^^^^^^^^^^^^^^^^^^^^^^^^^^^^^^^
facturasieli  |   File "//.venv/lib/python3.11/site-packages/django/db/backends/sqlite3/base.py", line 329, in execute
facturasieli  |     return super().execute(query, params)
facturasieli  |            ^^^^^^^^^^^^^^^^^^^^^^^^^^^^^^
facturasieli  | sqlite3.OperationalError: no such column: facturasieli_profile.last_login
facturasieli  | 
facturasieli  | The above exception was the direct cause of the following exception:
facturasieli  | 
facturasieli  | Traceback (most recent call last):
facturasieli  |   File "//.venv/lib/python3.11/site-packages/django/core/handlers/exception.py", line 55, in inner
facturasieli  |     response = get_response(request)
facturasieli  |                ^^^^^^^^^^^^^^^^^^^^^
facturasieli  |   File "/FacturaSieli/facturasieli/middleware.py", line 20, in __call__
facturasieli  |     profile = Profile.objects.get(email=request.user)
facturasieli  |               ^^^^^^^^^^^^^^^^^^^^^^^^^^^^^^^^^^^^^^^
facturasieli  |   File "//.venv/lib/python3.11/site-packages/django/db/models/manager.py", line 87, in manager_method
facturasieli  |     return getattr(self.get_queryset(), name)(*args, **kwargs)
facturasieli  |            ^^^^^^^^^^^^^^^^^^^^^^^^^^^^^^^^^^^^^^^^^^^^^^^^^^^
facturasieli  |   File "//.venv/lib/python3.11/site-packages/django/db/models/query.py", line 645, in get
facturasieli  |     num = len(clone)
facturasieli  |           ^^^^^^^^^^
facturasieli  |   File "//.venv/lib/python3.11/site-packages/django/db/models/query.py", line 382, in __len__
facturasieli  |     self._fetch_all()
facturasieli  |   File "//.venv/lib/python3.11/site-packages/django/db/models/query.py", line 1928, in _fetch_all
facturasieli  |     self._result_cache = list(self._iterable_class(self))
facturasieli  |                          ^^^^^^^^^^^^^^^^^^^^^^^^^^^^^^^^
facturasieli  |   File "//.venv/lib/python3.11/site-packages/django/db/models/query.py", line 91, in __iter__
facturasieli  |     results = compiler.execute_sql(
facturasieli  |               ^^^^^^^^^^^^^^^^^^^^^
facturasieli  |   File "//.venv/lib/python3.11/site-packages/django/db/models/sql/compiler.py", line 1562, in execute_sql
facturasieli  |     cursor.execute(sql, params)
facturasieli  |   File "//.venv/lib/python3.11/site-packages/django/db/backends/utils.py", line 122, in execute
facturasieli  |     return super().execute(sql, params)
facturasieli  |            ^^^^^^^^^^^^^^^^^^^^^^^^^^^^
facturasieli  |   File "//.venv/lib/python3.11/site-packages/django/db/backends/utils.py", line 79, in execute
facturasieli  |     return self._execute_with_wrappers(
facturasieli  |            ^^^^^^^^^^^^^^^^^^^^^^^^^^^^
facturasieli  |   File "//.venv/lib/python3.11/site-packages/django/db/backends/utils.py", line 92, in _execute_with_wrappers
facturasieli  |     return executor(sql, params, many, context)
facturasieli  |            ^^^^^^^^^^^^^^^^^^^^^^^^^^^^^^^^^^^^
facturasieli  |   File "//.venv/lib/python3.11/site-packages/django/db/backends/utils.py", line 100, in _execute
facturasieli  |     with self.db.wrap_database_errors:
facturasieli  |   File "//.venv/lib/python3.11/site-packages/django/db/utils.py", line 91, in __exit__
facturasieli  |     raise dj_exc_value.with_traceback(traceback) from exc_value
facturasieli  |   File "//.venv/lib/python3.11/site-packages/django/db/backends/utils.py", line 105, in _execute
facturasieli  |     return self.cursor.execute(sql, params)
facturasieli  |            ^^^^^^^^^^^^^^^^^^^^^^^^^^^^^^^^
facturasieli  |   File "//.venv/lib/python3.11/site-packages/django/db/backends/sqlite3/base.py", line 329, in execute
facturasieli  |     return super().execute(query, params)
facturasieli  |            ^^^^^^^^^^^^^^^^^^^^^^^^^^^^^^
facturasieli  | django.db.utils.OperationalError: no such column: facturasieli_profile.last_login
facturasieli  | [29/May/2024 10:54:09] "GET / HTTP/1.1" 500 121821
facturasieli  | Internal Server Error: /
facturasieli  | Traceback (most recent call last):
facturasieli  |   File "//.venv/lib/python3.11/site-packages/django/db/backends/utils.py", line 105, in _execute
facturasieli  |     return self.cursor.execute(sql, params)
facturasieli  |            ^^^^^^^^^^^^^^^^^^^^^^^^^^^^^^^^
facturasieli  |   File "//.venv/lib/python3.11/site-packages/django/db/backends/sqlite3/base.py", line 329, in execute
facturasieli  |     return super().execute(query, params)
facturasieli  |            ^^^^^^^^^^^^^^^^^^^^^^^^^^^^^^
facturasieli  | sqlite3.OperationalError: no such column: facturasieli_profile.last_login
facturasieli  | 
facturasieli  | The above exception was the direct cause of the following exception:
facturasieli  | 
facturasieli  | Traceback (most recent call last):
facturasieli  |   File "//.venv/lib/python3.11/site-packages/django/core/handlers/exception.py", line 55, in inner
facturasieli  |     response = get_response(request)
facturasieli  |                ^^^^^^^^^^^^^^^^^^^^^
facturasieli  |   File "/FacturaSieli/facturasieli/middleware.py", line 20, in __call__
facturasieli  |     profile = Profile.objects.get(email=request.user)
facturasieli  |               ^^^^^^^^^^^^^^^^^^^^^^^^^^^^^^^^^^^^^^^
facturasieli  |   File "//.venv/lib/python3.11/site-packages/django/db/models/manager.py", line 87, in manager_method
facturasieli  |     return getattr(self.get_queryset(), name)(*args, **kwargs)
facturasieli  |            ^^^^^^^^^^^^^^^^^^^^^^^^^^^^^^^^^^^^^^^^^^^^^^^^^^^
facturasieli  |   File "//.venv/lib/python3.11/site-packages/django/db/models/query.py", line 645, in get
facturasieli  |     num = len(clone)
facturasieli  |           ^^^^^^^^^^
facturasieli  |   File "//.venv/lib/python3.11/site-packages/django/db/models/query.py", line 382, in __len__
facturasieli  |     self._fetch_all()
facturasieli  |   File "//.venv/lib/python3.11/site-packages/django/db/models/query.py", line 1928, in _fetch_all
facturasieli  |     self._result_cache = list(self._iterable_class(self))
facturasieli  |                          ^^^^^^^^^^^^^^^^^^^^^^^^^^^^^^^^
facturasieli  |   File "//.venv/lib/python3.11/site-packages/django/db/models/query.py", line 91, in __iter__
facturasieli  |     results = compiler.execute_sql(
facturasieli  |               ^^^^^^^^^^^^^^^^^^^^^
facturasieli  |   File "//.venv/lib/python3.11/site-packages/django/db/models/sql/compiler.py", line 1562, in execute_sql
facturasieli  |     cursor.execute(sql, params)
facturasieli  |   File "//.venv/lib/python3.11/site-packages/django/db/backends/utils.py", line 122, in execute
facturasieli  |     return super().execute(sql, params)
facturasieli  |            ^^^^^^^^^^^^^^^^^^^^^^^^^^^^
facturasieli  |   File "//.venv/lib/python3.11/site-packages/django/db/backends/utils.py", line 79, in execute
facturasieli  |     return self._execute_with_wrappers(
facturasieli  |            ^^^^^^^^^^^^^^^^^^^^^^^^^^^^
facturasieli  |   File "//.venv/lib/python3.11/site-packages/django/db/backends/utils.py", line 92, in _execute_with_wrappers
facturasieli  |     return executor(sql, params, many, context)
facturasieli  |            ^^^^^^^^^^^^^^^^^^^^^^^^^^^^^^^^^^^^
facturasieli  |   File "//.venv/lib/python3.11/site-packages/django/db/backends/utils.py", line 100, in _execute
facturasieli  |     with self.db.wrap_database_errors:
facturasieli  |   File "//.venv/lib/python3.11/site-packages/django/db/utils.py", line 91, in __exit__
facturasieli  |     raise dj_exc_value.with_traceback(traceback) from exc_value
facturasieli  |   File "//.venv/lib/python3.11/site-packages/django/db/backends/utils.py", line 105, in _execute
facturasieli  |     return self.cursor.execute(sql, params)
facturasieli  |            ^^^^^^^^^^^^^^^^^^^^^^^^^^^^^^^^
facturasieli  |   File "//.venv/lib/python3.11/site-packages/django/db/backends/sqlite3/base.py", line 329, in execute
facturasieli  |     return super().execute(query, params)
facturasieli  |            ^^^^^^^^^^^^^^^^^^^^^^^^^^^^^^
facturasieli  | django.db.utils.OperationalError: no such column: facturasieli_profile.last_login
facturasieli  | [29/May/2024 10:55:14] "GET / HTTP/1.1" 500 121958
facturasieli  | /FacturaSieli/facturasieli/migrations/0001_initial.py changed, reloading.
facturasieli  | Performing system checks...
facturasieli  | 
facturasieli  | System check identified no issues (0 silenced).
facturasieli  | May 29, 2024 - 10:54:01
facturasieli  | Django version 5.0.6, using settings 'config.settings'
facturasieli  | Starting development server at http://0.0.0.0:8000/
facturasieli  | Quit the server with CONTROL-C.
facturasieli  | 
facturasieli  | Watching for file changes with StatReloader
facturasieli  | Exception in thread django-main-thread:
facturasieli  | Traceback (most recent call last):
facturasieli  |   File "//.venv/lib/python3.11/site-packages/django/db/backends/utils.py", line 103, in _execute
facturasieli  |     return self.cursor.execute(sql)
facturasieli  |            ^^^^^^^^^^^^^^^^^^^^^^^^
facturasieli  |   File "//.venv/lib/python3.11/site-packages/django/db/backends/sqlite3/base.py", line 325, in execute
facturasieli  |     return super().execute(query)
facturasieli  |            ^^^^^^^^^^^^^^^^^^^^^^
facturasieli  | sqlite3.OperationalError: disk I/O error
facturasieli  | 
facturasieli  | The above exception was the direct cause of the following exception:
facturasieli  | 
facturasieli  | Traceback (most recent call last):
facturasieli  |   File "/usr/lib/python3.11/threading.py", line 1038, in _bootstrap_inner
facturasieli  |     self.run()
facturasieli  |   File "/usr/lib/python3.11/threading.py", line 975, in run
facturasieli  |     self._target(*self._args, **self._kwargs)
facturasieli  |   File "//.venv/lib/python3.11/site-packages/django/utils/autoreload.py", line 64, in wrapper
facturasieli  |     fn(*args, **kwargs)
facturasieli  |   File "//.venv/lib/python3.11/site-packages/django/core/management/commands/runserver.py", line 136, in inner_run
facturasieli  |     self.check_migrations()
facturasieli  |   File "//.venv/lib/python3.11/site-packages/django/core/management/base.py", line 581, in check_migrations
facturasieli  |     executor = MigrationExecutor(connections[DEFAULT_DB_ALIAS])
facturasieli  |                ^^^^^^^^^^^^^^^^^^^^^^^^^^^^^^^^^^^^^^^^^^^^^^^^
facturasieli  |   File "//.venv/lib/python3.11/site-packages/django/db/migrations/executor.py", line 18, in __init__
facturasieli  |     self.loader = MigrationLoader(self.connection)
facturasieli  |                   ^^^^^^^^^^^^^^^^^^^^^^^^^^^^^^^^
facturasieli  |   File "//.venv/lib/python3.11/site-packages/django/db/migrations/loader.py", line 58, in __init__
facturasieli  |     self.build_graph()
facturasieli  |   File "//.venv/lib/python3.11/site-packages/django/db/migrations/loader.py", line 235, in build_graph
facturasieli  |     self.applied_migrations = recorder.applied_migrations()
facturasieli  |                               ^^^^^^^^^^^^^^^^^^^^^^^^^^^^^
facturasieli  |   File "//.venv/lib/python3.11/site-packages/django/db/migrations/recorder.py", line 89, in applied_migrations
facturasieli  |     if self.has_table():
facturasieli  |        ^^^^^^^^^^^^^^^^
facturasieli  |   File "//.venv/lib/python3.11/site-packages/django/db/migrations/recorder.py", line 64, in has_table
facturasieli  |     tables = self.connection.introspection.table_names(cursor)
facturasieli  |              ^^^^^^^^^^^^^^^^^^^^^^^^^^^^^^^^^^^^^^^^^^^^^^^^^
facturasieli  |   File "//.venv/lib/python3.11/site-packages/django/db/backends/base/introspection.py", line 58, in table_names
facturasieli  |     return get_names(cursor)
facturasieli  |            ^^^^^^^^^^^^^^^^^
facturasieli  |   File "//.venv/lib/python3.11/site-packages/django/db/backends/base/introspection.py", line 51, in get_names
facturasieli  |     for ti in self.get_table_list(cursor)
facturasieli  |               ^^^^^^^^^^^^^^^^^^^^^^^^^^^
facturasieli  |   File "//.venv/lib/python3.11/site-packages/django/db/backends/sqlite3/introspection.py", line 80, in get_table_list
facturasieli  |     cursor.execute(
facturasieli  |   File "//.venv/lib/python3.11/site-packages/django/db/backends/utils.py", line 122, in execute
facturasieli  |     return super().execute(sql, params)
facturasieli  |            ^^^^^^^^^^^^^^^^^^^^^^^^^^^^
facturasieli  |   File "//.venv/lib/python3.11/site-packages/django/db/backends/utils.py", line 79, in execute
facturasieli  |     return self._execute_with_wrappers(
facturasieli  |            ^^^^^^^^^^^^^^^^^^^^^^^^^^^^
facturasieli  |   File "//.venv/lib/python3.11/site-packages/django/db/backends/utils.py", line 92, in _execute_with_wrappers
facturasieli  |     return executor(sql, params, many, context)
facturasieli  |            ^^^^^^^^^^^^^^^^^^^^^^^^^^^^^^^^^^^^
facturasieli  |   File "//.venv/lib/python3.11/site-packages/django/db/backends/utils.py", line 100, in _execute
facturasieli  |     with self.db.wrap_database_errors:
facturasieli  |   File "//.venv/lib/python3.11/site-packages/django/db/utils.py", line 91, in __exit__
facturasieli  |     raise dj_exc_value.with_traceback(traceback) from exc_value
facturasieli  |   File "//.venv/lib/python3.11/site-packages/django/db/backends/utils.py", line 103, in _execute
facturasieli  |     return self.cursor.execute(sql)
facturasieli  |            ^^^^^^^^^^^^^^^^^^^^^^^^
facturasieli  |   File "//.venv/lib/python3.11/site-packages/django/db/backends/sqlite3/base.py", line 325, in execute
facturasieli  |     return super().execute(query)
facturasieli  |            ^^^^^^^^^^^^^^^^^^^^^^
facturasieli  | django.db.utils.OperationalError: disk I/O error
facturasieli  | Watching for file changes with StatReloader
facturasieli  | Internal Server Error: /
facturasieli  | Traceback (most recent call last):
facturasieli  |   File "//.venv/lib/python3.11/site-packages/django/contrib/sessions/backends/base.py", line 187, in _get_session
facturasieli  |     return self._session_cache
facturasieli  |            ^^^^^^^^^^^^^^^^^^^
facturasieli  | AttributeError: 'SessionStore' object has no attribute '_session_cache'
facturasieli  | 
facturasieli  | During handling of the above exception, another exception occurred:
facturasieli  | 
facturasieli  | Traceback (most recent call last):
facturasieli  |   File "//.venv/lib/python3.11/site-packages/django/db/backends/utils.py", line 105, in _execute
facturasieli  |     return self.cursor.execute(sql, params)
facturasieli  |            ^^^^^^^^^^^^^^^^^^^^^^^^^^^^^^^^
facturasieli  |   File "//.venv/lib/python3.11/site-packages/django/db/backends/sqlite3/base.py", line 329, in execute
facturasieli  |     return super().execute(query, params)
facturasieli  |            ^^^^^^^^^^^^^^^^^^^^^^^^^^^^^^
facturasieli  | sqlite3.OperationalError: no such table: django_session
facturasieli  | 
facturasieli  | The above exception was the direct cause of the following exception:
facturasieli  | 
facturasieli  | Traceback (most recent call last):
facturasieli  |   File "//.venv/lib/python3.11/site-packages/django/core/handlers/exception.py", line 55, in inner
facturasieli  |     response = get_response(request)
facturasieli  |                ^^^^^^^^^^^^^^^^^^^^^
facturasieli  |   File "/FacturaSieli/facturasieli/middleware.py", line 19, in __call__
facturasieli  |     if request.user.is_authenticated:
facturasieli  |        ^^^^^^^^^^^^^^^^^^^^^^^^^^^^^
facturasieli  |   File "//.venv/lib/python3.11/site-packages/django/utils/functional.py", line 251, in inner
facturasieli  |     self._setup()
facturasieli  |   File "//.venv/lib/python3.11/site-packages/django/utils/functional.py", line 404, in _setup
facturasieli  |     self._wrapped = self._setupfunc()
facturasieli  |                     ^^^^^^^^^^^^^^^^^
facturasieli  |   File "//.venv/lib/python3.11/site-packages/django/contrib/auth/middleware.py", line 33, in <lambda>
facturasieli  |     request.user = SimpleLazyObject(lambda: get_user(request))
facturasieli  |                                             ^^^^^^^^^^^^^^^^^
facturasieli  |   File "//.venv/lib/python3.11/site-packages/django/contrib/auth/middleware.py", line 13, in get_user
facturasieli  |     request._cached_user = auth.get_user(request)
facturasieli  |                            ^^^^^^^^^^^^^^^^^^^^^^
facturasieli  |   File "//.venv/lib/python3.11/site-packages/django/contrib/auth/__init__.py", line 209, in get_user
facturasieli  |     user_id = _get_user_session_key(request)
facturasieli  |               ^^^^^^^^^^^^^^^^^^^^^^^^^^^^^^
facturasieli  |   File "//.venv/lib/python3.11/site-packages/django/contrib/auth/__init__.py", line 62, in _get_user_session_key
facturasieli  |     return get_user_model()._meta.pk.to_python(request.session[SESSION_KEY])
facturasieli  |                                                ~~~~~~~~~~~~~~~^^^^^^^^^^^^^
facturasieli  |   File "//.venv/lib/python3.11/site-packages/django/contrib/sessions/backends/base.py", line 53, in __getitem__
facturasieli  |     return self._session[key]
facturasieli  |            ^^^^^^^^^^^^^
facturasieli  |   File "//.venv/lib/python3.11/site-packages/django/contrib/sessions/backends/base.py", line 192, in _get_session
facturasieli  |     self._session_cache = self.load()
facturasieli  |                           ^^^^^^^^^^^
facturasieli  |   File "//.venv/lib/python3.11/site-packages/django/contrib/sessions/backends/db.py", line 42, in load
facturasieli  |     s = self._get_session_from_db()
facturasieli  |         ^^^^^^^^^^^^^^^^^^^^^^^^^^^
facturasieli  |   File "//.venv/lib/python3.11/site-packages/django/contrib/sessions/backends/db.py", line 32, in _get_session_from_db
facturasieli  |     return self.model.objects.get(
facturasieli  |            ^^^^^^^^^^^^^^^^^^^^^^^
facturasieli  |   File "//.venv/lib/python3.11/site-packages/django/db/models/manager.py", line 87, in manager_method
facturasieli  |     return getattr(self.get_queryset(), name)(*args, **kwargs)
facturasieli  |            ^^^^^^^^^^^^^^^^^^^^^^^^^^^^^^^^^^^^^^^^^^^^^^^^^^^
facturasieli  |   File "//.venv/lib/python3.11/site-packages/django/db/models/query.py", line 645, in get
facturasieli  |     num = len(clone)
facturasieli  |           ^^^^^^^^^^
facturasieli  |   File "//.venv/lib/python3.11/site-packages/django/db/models/query.py", line 382, in __len__
facturasieli  |     self._fetch_all()
facturasieli  |   File "//.venv/lib/python3.11/site-packages/django/db/models/query.py", line 1928, in _fetch_all
facturasieli  |     self._result_cache = list(self._iterable_class(self))
facturasieli  |                          ^^^^^^^^^^^^^^^^^^^^^^^^^^^^^^^^
facturasieli  |   File "//.venv/lib/python3.11/site-packages/django/db/models/query.py", line 91, in __iter__
facturasieli  |     results = compiler.execute_sql(
facturasieli  |               ^^^^^^^^^^^^^^^^^^^^^
facturasieli  |   File "//.venv/lib/python3.11/site-packages/django/db/models/sql/compiler.py", line 1562, in execute_sql
facturasieli  |     cursor.execute(sql, params)
facturasieli  |   File "//.venv/lib/python3.11/site-packages/django/db/backends/utils.py", line 122, in execute
facturasieli  |     return super().execute(sql, params)
facturasieli  |            ^^^^^^^^^^^^^^^^^^^^^^^^^^^^
facturasieli  |   File "//.venv/lib/python3.11/site-packages/django/db/backends/utils.py", line 79, in execute
facturasieli  |     return self._execute_with_wrappers(
facturasieli  |            ^^^^^^^^^^^^^^^^^^^^^^^^^^^^
facturasieli  |   File "//.venv/lib/python3.11/site-packages/django/db/backends/utils.py", line 92, in _execute_with_wrappers
facturasieli  |     return executor(sql, params, many, context)
facturasieli  |            ^^^^^^^^^^^^^^^^^^^^^^^^^^^^^^^^^^^^
facturasieli  |   File "//.venv/lib/python3.11/site-packages/django/db/backends/utils.py", line 100, in _execute
facturasieli  |     with self.db.wrap_database_errors:
facturasieli  |   File "//.venv/lib/python3.11/site-packages/django/db/utils.py", line 91, in __exit__
facturasieli  |     raise dj_exc_value.with_traceback(traceback) from exc_value
facturasieli  |   File "//.venv/lib/python3.11/site-packages/django/db/backends/utils.py", line 105, in _execute
facturasieli  |     return self.cursor.execute(sql, params)
facturasieli  |            ^^^^^^^^^^^^^^^^^^^^^^^^^^^^^^^^
facturasieli  |   File "//.venv/lib/python3.11/site-packages/django/db/backends/sqlite3/base.py", line 329, in execute
facturasieli  |     return super().execute(query, params)
facturasieli  |            ^^^^^^^^^^^^^^^^^^^^^^^^^^^^^^
facturasieli  | django.db.utils.OperationalError: no such table: django_session
facturasieli  | [29/May/2024 11:01:50] "GET / HTTP/1.1" 500 162204
facturasieli  | Watching for file changes with StatReloader
facturasieli  | Internal Server Error: /
facturasieli  | Traceback (most recent call last):
facturasieli  |   File "//.venv/lib/python3.11/site-packages/django/contrib/sessions/backends/base.py", line 187, in _get_session
facturasieli  |     return self._session_cache
facturasieli  |            ^^^^^^^^^^^^^^^^^^^
facturasieli  | AttributeError: 'SessionStore' object has no attribute '_session_cache'
facturasieli  | 
facturasieli  | During handling of the above exception, another exception occurred:
facturasieli  | 
facturasieli  | Traceback (most recent call last):
facturasieli  |   File "//.venv/lib/python3.11/site-packages/django/db/backends/utils.py", line 105, in _execute
facturasieli  |     return self.cursor.execute(sql, params)
facturasieli  |            ^^^^^^^^^^^^^^^^^^^^^^^^^^^^^^^^
facturasieli  |   File "//.venv/lib/python3.11/site-packages/django/db/backends/sqlite3/base.py", line 329, in execute
facturasieli  |     return super().execute(query, params)
facturasieli  |            ^^^^^^^^^^^^^^^^^^^^^^^^^^^^^^
facturasieli  | sqlite3.OperationalError: no such table: django_session
facturasieli  | 
facturasieli  | The above exception was the direct cause of the following exception:
facturasieli  | 
facturasieli  | Traceback (most recent call last):
facturasieli  |   File "//.venv/lib/python3.11/site-packages/django/core/handlers/exception.py", line 55, in inner
facturasieli  |     response = get_response(request)
facturasieli  |                ^^^^^^^^^^^^^^^^^^^^^
facturasieli  |   File "/FacturaSieli/facturasieli/middleware.py", line 19, in __call__
facturasieli  |     if request.user.is_authenticated:
facturasieli  |        ^^^^^^^^^^^^^^^^^^^^^^^^^^^^^
facturasieli  |   File "//.venv/lib/python3.11/site-packages/django/utils/functional.py", line 251, in inner
facturasieli  |     self._setup()
facturasieli  |   File "//.venv/lib/python3.11/site-packages/django/utils/functional.py", line 404, in _setup
facturasieli  |     self._wrapped = self._setupfunc()
facturasieli  |                     ^^^^^^^^^^^^^^^^^
facturasieli  |   File "//.venv/lib/python3.11/site-packages/django/contrib/auth/middleware.py", line 33, in <lambda>
facturasieli  |     request.user = SimpleLazyObject(lambda: get_user(request))
facturasieli  |                                             ^^^^^^^^^^^^^^^^^
facturasieli  |   File "//.venv/lib/python3.11/site-packages/django/contrib/auth/middleware.py", line 13, in get_user
facturasieli  |     request._cached_user = auth.get_user(request)
facturasieli  |                            ^^^^^^^^^^^^^^^^^^^^^^
facturasieli  |   File "//.venv/lib/python3.11/site-packages/django/contrib/auth/__init__.py", line 209, in get_user
facturasieli  |     user_id = _get_user_session_key(request)
facturasieli  |               ^^^^^^^^^^^^^^^^^^^^^^^^^^^^^^
facturasieli  |   File "//.venv/lib/python3.11/site-packages/django/contrib/auth/__init__.py", line 62, in _get_user_session_key
facturasieli  |     return get_user_model()._meta.pk.to_python(request.session[SESSION_KEY])
facturasieli  |                                                ~~~~~~~~~~~~~~~^^^^^^^^^^^^^
facturasieli  |   File "//.venv/lib/python3.11/site-packages/django/contrib/sessions/backends/base.py", line 53, in __getitem__
facturasieli  |     return self._session[key]
facturasieli  |            ^^^^^^^^^^^^^
facturasieli  |   File "//.venv/lib/python3.11/site-packages/django/contrib/sessions/backends/base.py", line 192, in _get_session
facturasieli  |     self._session_cache = self.load()
facturasieli  |                           ^^^^^^^^^^^
facturasieli  |   File "//.venv/lib/python3.11/site-packages/django/contrib/sessions/backends/db.py", line 42, in load
facturasieli  |     s = self._get_session_from_db()
facturasieli  |         ^^^^^^^^^^^^^^^^^^^^^^^^^^^
facturasieli  |   File "//.venv/lib/python3.11/site-packages/django/contrib/sessions/backends/db.py", line 32, in _get_session_from_db
facturasieli  |     return self.model.objects.get(
facturasieli  |            ^^^^^^^^^^^^^^^^^^^^^^^
facturasieli  |   File "//.venv/lib/python3.11/site-packages/django/db/models/manager.py", line 87, in manager_method
facturasieli  |     return getattr(self.get_queryset(), name)(*args, **kwargs)
facturasieli  |            ^^^^^^^^^^^^^^^^^^^^^^^^^^^^^^^^^^^^^^^^^^^^^^^^^^^
facturasieli  |   File "//.venv/lib/python3.11/site-packages/django/db/models/query.py", line 645, in get
facturasieli  |     num = len(clone)
facturasieli  |           ^^^^^^^^^^
facturasieli  |   File "//.venv/lib/python3.11/site-packages/django/db/models/query.py", line 382, in __len__
facturasieli  |     self._fetch_all()
facturasieli  |   File "//.venv/lib/python3.11/site-packages/django/db/models/query.py", line 1928, in _fetch_all
facturasieli  |     self._result_cache = list(self._iterable_class(self))
facturasieli  |                          ^^^^^^^^^^^^^^^^^^^^^^^^^^^^^^^^
facturasieli  |   File "//.venv/lib/python3.11/site-packages/django/db/models/query.py", line 91, in __iter__
facturasieli  |     results = compiler.execute_sql(
facturasieli  |               ^^^^^^^^^^^^^^^^^^^^^
facturasieli  |   File "//.venv/lib/python3.11/site-packages/django/db/models/sql/compiler.py", line 1562, in execute_sql
facturasieli  |     cursor.execute(sql, params)
facturasieli  |   File "//.venv/lib/python3.11/site-packages/django/db/backends/utils.py", line 122, in execute
facturasieli  |     return super().execute(sql, params)
facturasieli  |            ^^^^^^^^^^^^^^^^^^^^^^^^^^^^
facturasieli  |   File "//.venv/lib/python3.11/site-packages/django/db/backends/utils.py", line 79, in execute
facturasieli  |     return self._execute_with_wrappers(
facturasieli  |            ^^^^^^^^^^^^^^^^^^^^^^^^^^^^
facturasieli  |   File "//.venv/lib/python3.11/site-packages/django/db/backends/utils.py", line 92, in _execute_with_wrappers
facturasieli  |     return executor(sql, params, many, context)
facturasieli  |            ^^^^^^^^^^^^^^^^^^^^^^^^^^^^^^^^^^^^
facturasieli  |   File "//.venv/lib/python3.11/site-packages/django/db/backends/utils.py", line 100, in _execute
facturasieli  |     with self.db.wrap_database_errors:
facturasieli  |   File "//.venv/lib/python3.11/site-packages/django/db/utils.py", line 91, in __exit__
facturasieli  |     raise dj_exc_value.with_traceback(traceback) from exc_value
facturasieli  |   File "//.venv/lib/python3.11/site-packages/django/db/backends/utils.py", line 105, in _execute
facturasieli  |     return self.cursor.execute(sql, params)
facturasieli  |            ^^^^^^^^^^^^^^^^^^^^^^^^^^^^^^^^
facturasieli  |   File "//.venv/lib/python3.11/site-packages/django/db/backends/sqlite3/base.py", line 329, in execute
facturasieli  |     return super().execute(query, params)
facturasieli  |            ^^^^^^^^^^^^^^^^^^^^^^^^^^^^^^
facturasieli  | django.db.utils.OperationalError: no such table: django_session
facturasieli  | [29/May/2024 11:02:10] "GET / HTTP/1.1" 500 162196
facturasieli  | Performing system checks...
facturasieli  | 
facturasieli  | System check identified no issues (0 silenced).
facturasieli  | May 29, 2024 - 11:01:58
facturasieli  | Django version 5.0.6, using settings 'config.settings'
facturasieli  | Starting development server at http://0.0.0.0:8000/
facturasieli  | Quit the server with CONTROL-C.
facturasieli  | 
facturasieli  | /FacturaSieli/facturasieli/migrations/0001_initial.py changed, reloading.
facturasieli  | Watching for file changes with StatReloader
facturasieli  | [29/May/2024 11:10:10] "GET / HTTP/1.1" 302 0
facturasieli  | [29/May/2024 11:10:10] "GET /en/ HTTP/1.1" 302 0
facturasieli  | [29/May/2024 11:10:11] "GET /en/custom_login/ HTTP/1.1" 200 3917
facturasieli  | [29/May/2024 11:10:27] "POST /en/custom_login/ HTTP/1.1" 200 4076
facturasieli  | [29/May/2024 11:10:33] "GET /en/register/ HTTP/1.1" 200 4429
facturasieli  | /FacturaSieli/facturasieli/migrations/__init__.py changed, reloading.
facturasieli  | Performing system checks...
facturasieli  | 
facturasieli  | System check identified no issues (0 silenced).
facturasieli  | 
facturasieli  | You have 19 unapplied migration(s). Your project may not work properly until you apply the migrations for app(s): admin, auth, contenttypes, facturasieli, sessions.
facturasieli  | Run 'python manage.py migrate' to apply them.
facturasieli  | May 29, 2024 - 11:09:04
facturasieli  | Django version 5.0.6, using settings 'config.settings'
facturasieli  | Starting development server at http://0.0.0.0:8000/
facturasieli  | Quit the server with CONTROL-C.
facturasieli  | 
facturasieli  | Watching for file changes with StatReloader
facturasieli  | Exception in thread django-main-thread:
facturasieli  | Traceback (most recent call last):
facturasieli  |   File "//.venv/lib/python3.11/site-packages/django/db/backends/utils.py", line 103, in _execute
facturasieli  |     return self.cursor.execute(sql)
facturasieli  |            ^^^^^^^^^^^^^^^^^^^^^^^^
facturasieli  |   File "//.venv/lib/python3.11/site-packages/django/db/backends/sqlite3/base.py", line 325, in execute
facturasieli  |     return super().execute(query)
facturasieli  |            ^^^^^^^^^^^^^^^^^^^^^^
facturasieli  | sqlite3.OperationalError: disk I/O error
facturasieli  | 
facturasieli  | The above exception was the direct cause of the following exception:
facturasieli  | 
facturasieli  | Traceback (most recent call last):
facturasieli  |   File "/usr/lib/python3.11/threading.py", line 1038, in _bootstrap_inner
facturasieli  |     self.run()
facturasieli  |   File "/usr/lib/python3.11/threading.py", line 975, in run
facturasieli  |     self._target(*self._args, **self._kwargs)
facturasieli  |   File "//.venv/lib/python3.11/site-packages/django/utils/autoreload.py", line 64, in wrapper
facturasieli  |     fn(*args, **kwargs)
facturasieli  |   File "//.venv/lib/python3.11/site-packages/django/core/management/commands/runserver.py", line 136, in inner_run
facturasieli  |     self.check_migrations()
facturasieli  |   File "//.venv/lib/python3.11/site-packages/django/core/management/base.py", line 581, in check_migrations
facturasieli  |     executor = MigrationExecutor(connections[DEFAULT_DB_ALIAS])
facturasieli  |                ^^^^^^^^^^^^^^^^^^^^^^^^^^^^^^^^^^^^^^^^^^^^^^^^
facturasieli  |   File "//.venv/lib/python3.11/site-packages/django/db/migrations/executor.py", line 18, in __init__
facturasieli  |     self.loader = MigrationLoader(self.connection)
facturasieli  |                   ^^^^^^^^^^^^^^^^^^^^^^^^^^^^^^^^
facturasieli  |   File "//.venv/lib/python3.11/site-packages/django/db/migrations/loader.py", line 58, in __init__
facturasieli  |     self.build_graph()
facturasieli  |   File "//.venv/lib/python3.11/site-packages/django/db/migrations/loader.py", line 235, in build_graph
facturasieli  |     self.applied_migrations = recorder.applied_migrations()
facturasieli  |                               ^^^^^^^^^^^^^^^^^^^^^^^^^^^^^
facturasieli  |   File "//.venv/lib/python3.11/site-packages/django/db/migrations/recorder.py", line 89, in applied_migrations
facturasieli  |     if self.has_table():
facturasieli  |        ^^^^^^^^^^^^^^^^
facturasieli  |   File "//.venv/lib/python3.11/site-packages/django/db/migrations/recorder.py", line 64, in has_table
facturasieli  |     tables = self.connection.introspection.table_names(cursor)
facturasieli  |              ^^^^^^^^^^^^^^^^^^^^^^^^^^^^^^^^^^^^^^^^^^^^^^^^^
facturasieli  |   File "//.venv/lib/python3.11/site-packages/django/db/backends/base/introspection.py", line 58, in table_names
facturasieli  |     return get_names(cursor)
facturasieli  |            ^^^^^^^^^^^^^^^^^
facturasieli  |   File "//.venv/lib/python3.11/site-packages/django/db/backends/base/introspection.py", line 51, in get_names
facturasieli  |     for ti in self.get_table_list(cursor)
facturasieli  |               ^^^^^^^^^^^^^^^^^^^^^^^^^^^
facturasieli  |   File "//.venv/lib/python3.11/site-packages/django/db/backends/sqlite3/introspection.py", line 80, in get_table_list
facturasieli  |     cursor.execute(
facturasieli  |   File "//.venv/lib/python3.11/site-packages/django/db/backends/utils.py", line 122, in execute
facturasieli  |     return super().execute(sql, params)
facturasieli  |            ^^^^^^^^^^^^^^^^^^^^^^^^^^^^
facturasieli  |   File "//.venv/lib/python3.11/site-packages/django/db/backends/utils.py", line 79, in execute
facturasieli  |     return self._execute_with_wrappers(
facturasieli  |            ^^^^^^^^^^^^^^^^^^^^^^^^^^^^
facturasieli  |   File "//.venv/lib/python3.11/site-packages/django/db/backends/utils.py", line 92, in _execute_with_wrappers
facturasieli  |     return executor(sql, params, many, context)
facturasieli  |            ^^^^^^^^^^^^^^^^^^^^^^^^^^^^^^^^^^^^
facturasieli  |   File "//.venv/lib/python3.11/site-packages/django/db/backends/utils.py", line 100, in _execute
facturasieli  |     with self.db.wrap_database_errors:
facturasieli  |   File "//.venv/lib/python3.11/site-packages/django/db/utils.py", line 91, in __exit__
facturasieli  |     raise dj_exc_value.with_traceback(traceback) from exc_value
facturasieli  |   File "//.venv/lib/python3.11/site-packages/django/db/backends/utils.py", line 103, in _execute
facturasieli  |     return self.cursor.execute(sql)
facturasieli  |            ^^^^^^^^^^^^^^^^^^^^^^^^
facturasieli  |   File "//.venv/lib/python3.11/site-packages/django/db/backends/sqlite3/base.py", line 325, in execute
facturasieli  |     return super().execute(query)
facturasieli  |            ^^^^^^^^^^^^^^^^^^^^^^
facturasieli  | django.db.utils.OperationalError: disk I/O error
facturasieli  | Watching for file changes with StatReloader
facturasieli  | Watching for file changes with StatReloader
facturasieli  | [29/May/2024 11:26:25] "GET /en/register/ HTTP/1.1" 200 5870
facturasieli  | [29/May/2024 11:27:44] "POST /en/register/ HTTP/1.1" 302 0
facturasieli  | [29/May/2024 11:27:44] "GET /en/welcome/ HTTP/1.1" 200 3180
facturasieli  | [29/May/2024 11:27:46] "GET /en/custom_login/ HTTP/1.1" 200 3917
facturasieli  | [29/May/2024 11:27:53] "POST /en/custom_login/ HTTP/1.1" 302 0
facturasieli  | [29/May/2024 11:27:53] "GET /en/ HTTP/1.1" 200 4239
facturasieli  | [29/May/2024 11:27:54] "GET /media/default_avatar.jpg HTTP/1.1" 302 0
facturasieli  | [29/May/2024 11:27:54] "GET /en/media/default_avatar.jpg HTTP/1.1" 200 2740
facturasieli  | [29/May/2024 11:28:28] "GET /invoice HTTP/1.1" 302 0
facturasieli  | [29/May/2024 11:28:28] "GET /en/invoice/ HTTP/1.1" 200 4808
facturasieli  | /FacturaSieli/facturasieli/views/__init__.py changed, reloading.
facturasieli  | Performing system checks...
facturasieli  | 
facturasieli  | System check identified no issues (0 silenced).
facturasieli  | May 29, 2024 - 11:25:52
facturasieli  | Django version 5.0.6, using settings 'config.settings'
facturasieli  | Starting development server at http://0.0.0.0:8000/
facturasieli  | Quit the server with CONTROL-C.
facturasieli  | 
facturasieli  | Watching for file changes with StatReloader
facturasieli  | Exception in thread django-main-thread:
facturasieli  | Traceback (most recent call last):
facturasieli  |   File "/usr/lib/python3.11/threading.py", line 1038, in _bootstrap_inner
facturasieli  |     self.run()
facturasieli  |   File "/usr/lib/python3.11/threading.py", line 975, in run
facturasieli  |     self._target(*self._args, **self._kwargs)
facturasieli  |   File "//.venv/lib/python3.11/site-packages/django/utils/autoreload.py", line 64, in wrapper
facturasieli  |     fn(*args, **kwargs)
facturasieli  |   File "//.venv/lib/python3.11/site-packages/django/core/management/commands/runserver.py", line 133, in inner_run
facturasieli  |     self.check(display_num_errors=True)
facturasieli  |   File "//.venv/lib/python3.11/site-packages/django/core/management/base.py", line 486, in check
facturasieli  |     all_issues = checks.run_checks(
facturasieli  |                  ^^^^^^^^^^^^^^^^^^
facturasieli  |   File "//.venv/lib/python3.11/site-packages/django/core/checks/registry.py", line 88, in run_checks
facturasieli  |     new_errors = check(app_configs=app_configs, databases=databases)
facturasieli  |                  ^^^^^^^^^^^^^^^^^^^^^^^^^^^^^^^^^^^^^^^^^^^^^^^^^^^
facturasieli  |   File "//.venv/lib/python3.11/site-packages/django/core/checks/urls.py", line 42, in check_url_namespaces_unique
facturasieli  |     all_namespaces = _load_all_namespaces(resolver)
facturasieli  |                      ^^^^^^^^^^^^^^^^^^^^^^^^^^^^^^
facturasieli  |   File "//.venv/lib/python3.11/site-packages/django/core/checks/urls.py", line 61, in _load_all_namespaces
facturasieli  |     url_patterns = getattr(resolver, "url_patterns", [])
facturasieli  |                    ^^^^^^^^^^^^^^^^^^^^^^^^^^^^^^^^^^^^^
facturasieli  |   File "//.venv/lib/python3.11/site-packages/django/utils/functional.py", line 47, in __get__
facturasieli  |     res = instance.__dict__[self.name] = self.func(instance)
facturasieli  |                                          ^^^^^^^^^^^^^^^^^^^
facturasieli  |   File "//.venv/lib/python3.11/site-packages/django/urls/resolvers.py", line 738, in url_patterns
facturasieli  |     patterns = getattr(self.urlconf_module, "urlpatterns", self.urlconf_module)
facturasieli  |                        ^^^^^^^^^^^^^^^^^^^
facturasieli  |   File "//.venv/lib/python3.11/site-packages/django/utils/functional.py", line 47, in __get__
facturasieli  |     res = instance.__dict__[self.name] = self.func(instance)
facturasieli  |                                          ^^^^^^^^^^^^^^^^^^^
facturasieli  |   File "//.venv/lib/python3.11/site-packages/django/urls/resolvers.py", line 731, in urlconf_module
facturasieli  |     return import_module(self.urlconf_name)
facturasieli  |            ^^^^^^^^^^^^^^^^^^^^^^^^^^^^^^^^
facturasieli  |   File "/usr/lib/python3.11/importlib/__init__.py", line 126, in import_module
facturasieli  |     return _bootstrap._gcd_import(name[level:], package, level)
facturasieli  |            ^^^^^^^^^^^^^^^^^^^^^^^^^^^^^^^^^^^^^^^^^^^^^^^^^^^^
facturasieli  |   File "<frozen importlib._bootstrap>", line 1206, in _gcd_import
facturasieli  |   File "<frozen importlib._bootstrap>", line 1178, in _find_and_load
facturasieli  |   File "<frozen importlib._bootstrap>", line 1149, in _find_and_load_unlocked
facturasieli  |   File "<frozen importlib._bootstrap>", line 690, in _load_unlocked
facturasieli  |   File "<frozen importlib._bootstrap_external>", line 940, in exec_module
facturasieli  |   File "<frozen importlib._bootstrap>", line 241, in _call_with_frames_removed
facturasieli  |   File "/FacturaSieli/config/urls.py", line 34, in <module>
facturasieli  |     path('', include('facturasieli.urls')),
facturasieli  |              ^^^^^^^^^^^^^^^^^^^^^^^^^^^^
facturasieli  |   File "//.venv/lib/python3.11/site-packages/django/urls/conf.py", line 39, in include
facturasieli  |     urlconf_module = import_module(urlconf_module)
facturasieli  |                      ^^^^^^^^^^^^^^^^^^^^^^^^^^^^^
facturasieli  |   File "/usr/lib/python3.11/importlib/__init__.py", line 126, in import_module
facturasieli  |     return _bootstrap._gcd_import(name[level:], package, level)
facturasieli  |            ^^^^^^^^^^^^^^^^^^^^^^^^^^^^^^^^^^^^^^^^^^^^^^^^^^^^
facturasieli  |   File "<frozen importlib._bootstrap>", line 1206, in _gcd_import
facturasieli  |   File "<frozen importlib._bootstrap>", line 1178, in _find_and_load
facturasieli  |   File "<frozen importlib._bootstrap>", line 1149, in _find_and_load_unlocked
facturasieli  |   File "<frozen importlib._bootstrap>", line 690, in _load_unlocked
facturasieli  |   File "<frozen importlib._bootstrap_external>", line 940, in exec_module
facturasieli  |   File "<frozen importlib._bootstrap>", line 241, in _call_with_frames_removed
facturasieli  |   File "/FacturaSieli/facturasieli/urls.py", line 12, in <module>
facturasieli  |     from facturasieli.views.invoice_view import invoice_view, invoice_success
facturasieli  | ModuleNotFoundError: No module named 'facturasieli.views.invoice_view'
facturasieli  | /FacturaSieli/facturasieli/views/invoice/__init__.py changed, reloading.
facturasieli  | Performing system checks...
facturasieli  | 
facturasieli  | Watching for file changes with StatReloader
facturasieli  | Exception in thread django-main-thread:
facturasieli  | Traceback (most recent call last):
facturasieli  |   File "/usr/lib/python3.11/threading.py", line 1038, in _bootstrap_inner
facturasieli  |     self.run()
facturasieli  |   File "/usr/lib/python3.11/threading.py", line 975, in run
facturasieli  |     self._target(*self._args, **self._kwargs)
facturasieli  |   File "//.venv/lib/python3.11/site-packages/django/utils/autoreload.py", line 64, in wrapper
facturasieli  |     fn(*args, **kwargs)
facturasieli  |   File "//.venv/lib/python3.11/site-packages/django/core/management/commands/runserver.py", line 133, in inner_run
facturasieli  |     self.check(display_num_errors=True)
facturasieli  |   File "//.venv/lib/python3.11/site-packages/django/core/management/base.py", line 486, in check
facturasieli  |     all_issues = checks.run_checks(
facturasieli  |                  ^^^^^^^^^^^^^^^^^^
facturasieli  |   File "//.venv/lib/python3.11/site-packages/django/core/checks/registry.py", line 88, in run_checks
facturasieli  |     new_errors = check(app_configs=app_configs, databases=databases)
facturasieli  |                  ^^^^^^^^^^^^^^^^^^^^^^^^^^^^^^^^^^^^^^^^^^^^^^^^^^^
facturasieli  |   File "//.venv/lib/python3.11/site-packages/django/core/checks/urls.py", line 42, in check_url_namespaces_unique
facturasieli  |     all_namespaces = _load_all_namespaces(resolver)
facturasieli  |                      ^^^^^^^^^^^^^^^^^^^^^^^^^^^^^^
facturasieli  |   File "//.venv/lib/python3.11/site-packages/django/core/checks/urls.py", line 61, in _load_all_namespaces
facturasieli  |     url_patterns = getattr(resolver, "url_patterns", [])
facturasieli  |                    ^^^^^^^^^^^^^^^^^^^^^^^^^^^^^^^^^^^^^
facturasieli  |   File "//.venv/lib/python3.11/site-packages/django/utils/functional.py", line 47, in __get__
facturasieli  |     res = instance.__dict__[self.name] = self.func(instance)
facturasieli  |                                          ^^^^^^^^^^^^^^^^^^^
facturasieli  |   File "//.venv/lib/python3.11/site-packages/django/urls/resolvers.py", line 738, in url_patterns
facturasieli  |     patterns = getattr(self.urlconf_module, "urlpatterns", self.urlconf_module)
facturasieli  |                        ^^^^^^^^^^^^^^^^^^^
facturasieli  |   File "//.venv/lib/python3.11/site-packages/django/utils/functional.py", line 47, in __get__
facturasieli  |     res = instance.__dict__[self.name] = self.func(instance)
facturasieli  |                                          ^^^^^^^^^^^^^^^^^^^
facturasieli  |   File "//.venv/lib/python3.11/site-packages/django/urls/resolvers.py", line 731, in urlconf_module
facturasieli  |     return import_module(self.urlconf_name)
facturasieli  |            ^^^^^^^^^^^^^^^^^^^^^^^^^^^^^^^^
facturasieli  |   File "/usr/lib/python3.11/importlib/__init__.py", line 126, in import_module
facturasieli  |     return _bootstrap._gcd_import(name[level:], package, level)
facturasieli  |            ^^^^^^^^^^^^^^^^^^^^^^^^^^^^^^^^^^^^^^^^^^^^^^^^^^^^
facturasieli  |   File "<frozen importlib._bootstrap>", line 1206, in _gcd_import
facturasieli  |   File "<frozen importlib._bootstrap>", line 1178, in _find_and_load
facturasieli  |   File "<frozen importlib._bootstrap>", line 1149, in _find_and_load_unlocked
facturasieli  |   File "<frozen importlib._bootstrap>", line 690, in _load_unlocked
facturasieli  |   File "<frozen importlib._bootstrap_external>", line 940, in exec_module
facturasieli  |   File "<frozen importlib._bootstrap>", line 241, in _call_with_frames_removed
facturasieli  |   File "/FacturaSieli/config/urls.py", line 34, in <module>
facturasieli  |     path('', include('facturasieli.urls')),
facturasieli  |              ^^^^^^^^^^^^^^^^^^^^^^^^^^^^
facturasieli  |   File "//.venv/lib/python3.11/site-packages/django/urls/conf.py", line 39, in include
facturasieli  |     urlconf_module = import_module(urlconf_module)
facturasieli  |                      ^^^^^^^^^^^^^^^^^^^^^^^^^^^^^
facturasieli  |   File "/usr/lib/python3.11/importlib/__init__.py", line 126, in import_module
facturasieli  |     return _bootstrap._gcd_import(name[level:], package, level)
facturasieli  |            ^^^^^^^^^^^^^^^^^^^^^^^^^^^^^^^^^^^^^^^^^^^^^^^^^^^^
facturasieli  |   File "<frozen importlib._bootstrap>", line 1206, in _gcd_import
facturasieli  |   File "<frozen importlib._bootstrap>", line 1178, in _find_and_load
facturasieli  |   File "<frozen importlib._bootstrap>", line 1149, in _find_and_load_unlocked
facturasieli  |   File "<frozen importlib._bootstrap>", line 690, in _load_unlocked
facturasieli  |   File "<frozen importlib._bootstrap_external>", line 940, in exec_module
facturasieli  |   File "<frozen importlib._bootstrap>", line 241, in _call_with_frames_removed
facturasieli  |   File "/FacturaSieli/facturasieli/urls.py", line 12, in <module>
facturasieli  |     from facturasieli.views.invoice_view import invoice_view, invoice_success
facturasieli  | ModuleNotFoundError: No module named 'facturasieli.views.invoice_view'
facturasieli  | /FacturaSieli/facturasieli/views/invoice/invoice_view.py changed, reloading.
facturasieli  | Performing system checks...
facturasieli  | 
facturasieli  | Watching for file changes with StatReloader
facturasieli  | Exception in thread django-main-thread:
facturasieli  | Traceback (most recent call last):
facturasieli  |   File "/usr/lib/python3.11/threading.py", line 1038, in _bootstrap_inner
facturasieli  |     self.run()
facturasieli  |   File "/usr/lib/python3.11/threading.py", line 975, in run
facturasieli  |     self._target(*self._args, **self._kwargs)
facturasieli  |   File "//.venv/lib/python3.11/site-packages/django/utils/autoreload.py", line 64, in wrapper
facturasieli  |     fn(*args, **kwargs)
facturasieli  |   File "//.venv/lib/python3.11/site-packages/django/core/management/commands/runserver.py", line 133, in inner_run
facturasieli  |     self.check(display_num_errors=True)
facturasieli  |   File "//.venv/lib/python3.11/site-packages/django/core/management/base.py", line 486, in check
facturasieli  |     all_issues = checks.run_checks(
facturasieli  |                  ^^^^^^^^^^^^^^^^^^
facturasieli  |   File "//.venv/lib/python3.11/site-packages/django/core/checks/registry.py", line 88, in run_checks
facturasieli  |     new_errors = check(app_configs=app_configs, databases=databases)
facturasieli  |                  ^^^^^^^^^^^^^^^^^^^^^^^^^^^^^^^^^^^^^^^^^^^^^^^^^^^
facturasieli  |   File "//.venv/lib/python3.11/site-packages/django/core/checks/urls.py", line 42, in check_url_namespaces_unique
facturasieli  |     all_namespaces = _load_all_namespaces(resolver)
facturasieli  |                      ^^^^^^^^^^^^^^^^^^^^^^^^^^^^^^
facturasieli  |   File "//.venv/lib/python3.11/site-packages/django/core/checks/urls.py", line 61, in _load_all_namespaces
facturasieli  |     url_patterns = getattr(resolver, "url_patterns", [])
facturasieli  |                    ^^^^^^^^^^^^^^^^^^^^^^^^^^^^^^^^^^^^^
facturasieli  |   File "//.venv/lib/python3.11/site-packages/django/utils/functional.py", line 47, in __get__
facturasieli  |     res = instance.__dict__[self.name] = self.func(instance)
facturasieli  |                                          ^^^^^^^^^^^^^^^^^^^
facturasieli  |   File "//.venv/lib/python3.11/site-packages/django/urls/resolvers.py", line 738, in url_patterns
facturasieli  |     patterns = getattr(self.urlconf_module, "urlpatterns", self.urlconf_module)
facturasieli  |                        ^^^^^^^^^^^^^^^^^^^
facturasieli  |   File "//.venv/lib/python3.11/site-packages/django/utils/functional.py", line 47, in __get__
facturasieli  |     res = instance.__dict__[self.name] = self.func(instance)
facturasieli  |                                          ^^^^^^^^^^^^^^^^^^^
facturasieli  |   File "//.venv/lib/python3.11/site-packages/django/urls/resolvers.py", line 731, in urlconf_module
facturasieli  |     return import_module(self.urlconf_name)
facturasieli  |            ^^^^^^^^^^^^^^^^^^^^^^^^^^^^^^^^
facturasieli  |   File "/usr/lib/python3.11/importlib/__init__.py", line 126, in import_module
facturasieli  |     return _bootstrap._gcd_import(name[level:], package, level)
facturasieli  |            ^^^^^^^^^^^^^^^^^^^^^^^^^^^^^^^^^^^^^^^^^^^^^^^^^^^^
facturasieli  |   File "<frozen importlib._bootstrap>", line 1206, in _gcd_import
facturasieli  |   File "<frozen importlib._bootstrap>", line 1178, in _find_and_load
facturasieli  |   File "<frozen importlib._bootstrap>", line 1149, in _find_and_load_unlocked
facturasieli  |   File "<frozen importlib._bootstrap>", line 690, in _load_unlocked
facturasieli  |   File "<frozen importlib._bootstrap_external>", line 940, in exec_module
facturasieli  |   File "<frozen importlib._bootstrap>", line 241, in _call_with_frames_removed
facturasieli  |   File "/FacturaSieli/config/urls.py", line 34, in <module>
facturasieli  |     path('', include('facturasieli.urls')),
facturasieli  |              ^^^^^^^^^^^^^^^^^^^^^^^^^^^^
facturasieli  |   File "//.venv/lib/python3.11/site-packages/django/urls/conf.py", line 39, in include
facturasieli  |     urlconf_module = import_module(urlconf_module)
facturasieli  |                      ^^^^^^^^^^^^^^^^^^^^^^^^^^^^^
facturasieli  |   File "/usr/lib/python3.11/importlib/__init__.py", line 126, in import_module
facturasieli  |     return _bootstrap._gcd_import(name[level:], package, level)
facturasieli  |            ^^^^^^^^^^^^^^^^^^^^^^^^^^^^^^^^^^^^^^^^^^^^^^^^^^^^
facturasieli  |   File "<frozen importlib._bootstrap>", line 1206, in _gcd_import
facturasieli  |   File "<frozen importlib._bootstrap>", line 1178, in _find_and_load
facturasieli  |   File "<frozen importlib._bootstrap>", line 1149, in _find_and_load_unlocked
facturasieli  |   File "<frozen importlib._bootstrap>", line 690, in _load_unlocked
facturasieli  |   File "<frozen importlib._bootstrap_external>", line 940, in exec_module
facturasieli  |   File "<frozen importlib._bootstrap>", line 241, in _call_with_frames_removed
facturasieli  |   File "/FacturaSieli/facturasieli/urls.py", line 12, in <module>
facturasieli  |     from facturasieli.views.invoice_view import invoice_view, invoice_success
facturasieli  | ModuleNotFoundError: No module named 'facturasieli.views.invoice_view'
facturasieli  | Performing system checks...
facturasieli  | 
facturasieli  | /FacturaSieli/facturasieli/views/__init__.py changed, reloading.
facturasieli  | Watching for file changes with StatReloader
facturasieli  | Performing system checks...
facturasieli  | 
facturasieli  | System check identified no issues (0 silenced).
facturasieli  | May 29, 2024 - 11:43:50
facturasieli  | Django version 5.0.6, using settings 'config.settings'
facturasieli  | Starting development server at http://0.0.0.0:8000/
facturasieli  | Quit the server with CONTROL-C.
facturasieli  | 
facturasieli  | /FacturaSieli/facturasieli/urls.py changed, reloading.
facturasieli  | Watching for file changes with StatReloader
facturasieli  | Exception in thread django-main-thread:
facturasieli  | Traceback (most recent call last):
facturasieli  |   File "/usr/lib/python3.11/threading.py", line 1038, in _bootstrap_inner
facturasieli  |     self.run()
facturasieli  |   File "/usr/lib/python3.11/threading.py", line 975, in run
facturasieli  |     self._target(*self._args, **self._kwargs)
facturasieli  |   File "//.venv/lib/python3.11/site-packages/django/utils/autoreload.py", line 64, in wrapper
facturasieli  |     fn(*args, **kwargs)
facturasieli  |   File "//.venv/lib/python3.11/site-packages/django/core/management/commands/runserver.py", line 133, in inner_run
facturasieli  |     self.check(display_num_errors=True)
facturasieli  |   File "//.venv/lib/python3.11/site-packages/django/core/management/base.py", line 486, in check
facturasieli  |     all_issues = checks.run_checks(
facturasieli  |                  ^^^^^^^^^^^^^^^^^^
facturasieli  |   File "//.venv/lib/python3.11/site-packages/django/core/checks/registry.py", line 88, in run_checks
facturasieli  |     new_errors = check(app_configs=app_configs, databases=databases)
facturasieli  |                  ^^^^^^^^^^^^^^^^^^^^^^^^^^^^^^^^^^^^^^^^^^^^^^^^^^^
facturasieli  |   File "//.venv/lib/python3.11/site-packages/django/core/checks/urls.py", line 42, in check_url_namespaces_unique
facturasieli  |     all_namespaces = _load_all_namespaces(resolver)
facturasieli  |                      ^^^^^^^^^^^^^^^^^^^^^^^^^^^^^^
facturasieli  |   File "//.venv/lib/python3.11/site-packages/django/core/checks/urls.py", line 61, in _load_all_namespaces
facturasieli  |     url_patterns = getattr(resolver, "url_patterns", [])
facturasieli  |                    ^^^^^^^^^^^^^^^^^^^^^^^^^^^^^^^^^^^^^
facturasieli  |   File "//.venv/lib/python3.11/site-packages/django/utils/functional.py", line 47, in __get__
facturasieli  |     res = instance.__dict__[self.name] = self.func(instance)
facturasieli  |                                          ^^^^^^^^^^^^^^^^^^^
facturasieli  |   File "//.venv/lib/python3.11/site-packages/django/urls/resolvers.py", line 738, in url_patterns
facturasieli  |     patterns = getattr(self.urlconf_module, "urlpatterns", self.urlconf_module)
facturasieli  |                        ^^^^^^^^^^^^^^^^^^^
facturasieli  |   File "//.venv/lib/python3.11/site-packages/django/utils/functional.py", line 47, in __get__
facturasieli  |     res = instance.__dict__[self.name] = self.func(instance)
facturasieli  |                                          ^^^^^^^^^^^^^^^^^^^
facturasieli  |   File "//.venv/lib/python3.11/site-packages/django/urls/resolvers.py", line 731, in urlconf_module
facturasieli  |     return import_module(self.urlconf_name)
facturasieli  |            ^^^^^^^^^^^^^^^^^^^^^^^^^^^^^^^^
facturasieli  |   File "/usr/lib/python3.11/importlib/__init__.py", line 126, in import_module
facturasieli  |     return _bootstrap._gcd_import(name[level:], package, level)
facturasieli  |            ^^^^^^^^^^^^^^^^^^^^^^^^^^^^^^^^^^^^^^^^^^^^^^^^^^^^
facturasieli  |   File "<frozen importlib._bootstrap>", line 1206, in _gcd_import
facturasieli  |   File "<frozen importlib._bootstrap>", line 1178, in _find_and_load
facturasieli  |   File "<frozen importlib._bootstrap>", line 1149, in _find_and_load_unlocked
facturasieli  |   File "<frozen importlib._bootstrap>", line 690, in _load_unlocked
facturasieli  |   File "<frozen importlib._bootstrap_external>", line 940, in exec_module
facturasieli  |   File "<frozen importlib._bootstrap>", line 241, in _call_with_frames_removed
facturasieli  |   File "/FacturaSieli/config/urls.py", line 34, in <module>
facturasieli  |     path('', include('facturasieli.urls')),
facturasieli  |              ^^^^^^^^^^^^^^^^^^^^^^^^^^^^
facturasieli  |   File "//.venv/lib/python3.11/site-packages/django/urls/conf.py", line 39, in include
facturasieli  |     urlconf_module = import_module(urlconf_module)
facturasieli  |                      ^^^^^^^^^^^^^^^^^^^^^^^^^^^^^
facturasieli  |   File "/usr/lib/python3.11/importlib/__init__.py", line 126, in import_module
facturasieli  |     return _bootstrap._gcd_import(name[level:], package, level)
facturasieli  |            ^^^^^^^^^^^^^^^^^^^^^^^^^^^^^^^^^^^^^^^^^^^^^^^^^^^^
facturasieli  |   File "<frozen importlib._bootstrap>", line 1206, in _gcd_import
facturasieli  |   File "<frozen importlib._bootstrap>", line 1178, in _find_and_load
facturasieli  |   File "<frozen importlib._bootstrap>", line 1149, in _find_and_load_unlocked
facturasieli  |   File "<frozen importlib._bootstrap>", line 690, in _load_unlocked
facturasieli  |   File "<frozen importlib._bootstrap_external>", line 940, in exec_module
facturasieli  |   File "<frozen importlib._bootstrap>", line 241, in _call_with_frames_removed
facturasieli  |   File "/FacturaSieli/facturasieli/urls.py", line 12, in <module>
facturasieli  |     from facturasieli.views.invoice_view import invoice_view, invoice_success
facturasieli  | ModuleNotFoundError: No module named 'facturasieli.views.invoice_view'
facturasieli  | Watching for file changes with StatReloader
facturasieli  | Exception in thread django-main-thread:
facturasieli  | Traceback (most recent call last):
facturasieli  |   File "/usr/lib/python3.11/threading.py", line 1038, in _bootstrap_inner
facturasieli  |     self.run()
facturasieli  |   File "/usr/lib/python3.11/threading.py", line 975, in run
facturasieli  |     self._target(*self._args, **self._kwargs)
facturasieli  |   File "//.venv/lib/python3.11/site-packages/django/utils/autoreload.py", line 64, in wrapper
facturasieli  |     fn(*args, **kwargs)
facturasieli  |   File "//.venv/lib/python3.11/site-packages/django/core/management/commands/runserver.py", line 133, in inner_run
facturasieli  |     self.check(display_num_errors=True)
facturasieli  |   File "//.venv/lib/python3.11/site-packages/django/core/management/base.py", line 486, in check
facturasieli  |     all_issues = checks.run_checks(
facturasieli  |                  ^^^^^^^^^^^^^^^^^^
facturasieli  |   File "//.venv/lib/python3.11/site-packages/django/core/checks/registry.py", line 88, in run_checks
facturasieli  |     new_errors = check(app_configs=app_configs, databases=databases)
facturasieli  |                  ^^^^^^^^^^^^^^^^^^^^^^^^^^^^^^^^^^^^^^^^^^^^^^^^^^^
facturasieli  |   File "//.venv/lib/python3.11/site-packages/django/core/checks/urls.py", line 42, in check_url_namespaces_unique
facturasieli  |     all_namespaces = _load_all_namespaces(resolver)
facturasieli  |                      ^^^^^^^^^^^^^^^^^^^^^^^^^^^^^^
facturasieli  |   File "//.venv/lib/python3.11/site-packages/django/core/checks/urls.py", line 61, in _load_all_namespaces
facturasieli  |     url_patterns = getattr(resolver, "url_patterns", [])
facturasieli  |                    ^^^^^^^^^^^^^^^^^^^^^^^^^^^^^^^^^^^^^
facturasieli  |   File "//.venv/lib/python3.11/site-packages/django/utils/functional.py", line 47, in __get__
facturasieli  |     res = instance.__dict__[self.name] = self.func(instance)
facturasieli  |                                          ^^^^^^^^^^^^^^^^^^^
facturasieli  |   File "//.venv/lib/python3.11/site-packages/django/urls/resolvers.py", line 738, in url_patterns
facturasieli  |     patterns = getattr(self.urlconf_module, "urlpatterns", self.urlconf_module)
facturasieli  |                        ^^^^^^^^^^^^^^^^^^^
facturasieli  |   File "//.venv/lib/python3.11/site-packages/django/utils/functional.py", line 47, in __get__
facturasieli  |     res = instance.__dict__[self.name] = self.func(instance)
facturasieli  |                                          ^^^^^^^^^^^^^^^^^^^
facturasieli  |   File "//.venv/lib/python3.11/site-packages/django/urls/resolvers.py", line 731, in urlconf_module
facturasieli  |     return import_module(self.urlconf_name)
facturasieli  |            ^^^^^^^^^^^^^^^^^^^^^^^^^^^^^^^^
facturasieli  |   File "/usr/lib/python3.11/importlib/__init__.py", line 126, in import_module
facturasieli  |     return _bootstrap._gcd_import(name[level:], package, level)
facturasieli  |            ^^^^^^^^^^^^^^^^^^^^^^^^^^^^^^^^^^^^^^^^^^^^^^^^^^^^
facturasieli  |   File "<frozen importlib._bootstrap>", line 1206, in _gcd_import
facturasieli  |   File "<frozen importlib._bootstrap>", line 1178, in _find_and_load
facturasieli  |   File "<frozen importlib._bootstrap>", line 1149, in _find_and_load_unlocked
facturasieli  |   File "<frozen importlib._bootstrap>", line 690, in _load_unlocked
facturasieli  |   File "<frozen importlib._bootstrap_external>", line 940, in exec_module
facturasieli  |   File "<frozen importlib._bootstrap>", line 241, in _call_with_frames_removed
facturasieli  |   File "/FacturaSieli/config/urls.py", line 34, in <module>
facturasieli  |     path('', include('facturasieli.urls')),
facturasieli  |              ^^^^^^^^^^^^^^^^^^^^^^^^^^^^
facturasieli  |   File "//.venv/lib/python3.11/site-packages/django/urls/conf.py", line 39, in include
facturasieli  |     urlconf_module = import_module(urlconf_module)
facturasieli  |                      ^^^^^^^^^^^^^^^^^^^^^^^^^^^^^
facturasieli  |   File "/usr/lib/python3.11/importlib/__init__.py", line 126, in import_module
facturasieli  |     return _bootstrap._gcd_import(name[level:], package, level)
facturasieli  |            ^^^^^^^^^^^^^^^^^^^^^^^^^^^^^^^^^^^^^^^^^^^^^^^^^^^^
facturasieli  |   File "<frozen importlib._bootstrap>", line 1206, in _gcd_import
facturasieli  |   File "<frozen importlib._bootstrap>", line 1178, in _find_and_load
facturasieli  |   File "<frozen importlib._bootstrap>", line 1149, in _find_and_load_unlocked
facturasieli  |   File "<frozen importlib._bootstrap>", line 690, in _load_unlocked
facturasieli  |   File "<frozen importlib._bootstrap_external>", line 940, in exec_module
facturasieli  |   File "<frozen importlib._bootstrap>", line 241, in _call_with_frames_removed
facturasieli  |   File "/FacturaSieli/facturasieli/urls.py", line 12, in <module>
facturasieli  |     from facturasieli.views.invoice_view import invoice_view, invoice_success
facturasieli  | ModuleNotFoundError: No module named 'facturasieli.views.invoice_view'
facturasieli  | Watching for file changes with StatReloader
facturasieli  | Exception in thread django-main-thread:
facturasieli  | Traceback (most recent call last):
facturasieli  |   File "/usr/lib/python3.11/threading.py", line 1038, in _bootstrap_inner
facturasieli  |     self.run()
facturasieli  |   File "/usr/lib/python3.11/threading.py", line 975, in run
facturasieli  |     self._target(*self._args, **self._kwargs)
facturasieli  |   File "//.venv/lib/python3.11/site-packages/django/utils/autoreload.py", line 64, in wrapper
facturasieli  |     fn(*args, **kwargs)
facturasieli  |   File "//.venv/lib/python3.11/site-packages/django/core/management/commands/runserver.py", line 133, in inner_run
facturasieli  |     self.check(display_num_errors=True)
facturasieli  |   File "//.venv/lib/python3.11/site-packages/django/core/management/base.py", line 486, in check
facturasieli  |     all_issues = checks.run_checks(
facturasieli  |                  ^^^^^^^^^^^^^^^^^^
facturasieli  |   File "//.venv/lib/python3.11/site-packages/django/core/checks/registry.py", line 88, in run_checks
facturasieli  |     new_errors = check(app_configs=app_configs, databases=databases)
facturasieli  |                  ^^^^^^^^^^^^^^^^^^^^^^^^^^^^^^^^^^^^^^^^^^^^^^^^^^^
facturasieli  |   File "//.venv/lib/python3.11/site-packages/django/core/checks/urls.py", line 42, in check_url_namespaces_unique
facturasieli  |     all_namespaces = _load_all_namespaces(resolver)
facturasieli  |                      ^^^^^^^^^^^^^^^^^^^^^^^^^^^^^^
facturasieli  |   File "//.venv/lib/python3.11/site-packages/django/core/checks/urls.py", line 61, in _load_all_namespaces
facturasieli  |     url_patterns = getattr(resolver, "url_patterns", [])
facturasieli  |                    ^^^^^^^^^^^^^^^^^^^^^^^^^^^^^^^^^^^^^
facturasieli  |   File "//.venv/lib/python3.11/site-packages/django/utils/functional.py", line 47, in __get__
facturasieli  |     res = instance.__dict__[self.name] = self.func(instance)
facturasieli  |                                          ^^^^^^^^^^^^^^^^^^^
facturasieli  |   File "//.venv/lib/python3.11/site-packages/django/urls/resolvers.py", line 738, in url_patterns
facturasieli  |     patterns = getattr(self.urlconf_module, "urlpatterns", self.urlconf_module)
facturasieli  |                        ^^^^^^^^^^^^^^^^^^^
facturasieli  |   File "//.venv/lib/python3.11/site-packages/django/utils/functional.py", line 47, in __get__
facturasieli  |     res = instance.__dict__[self.name] = self.func(instance)
facturasieli  |                                          ^^^^^^^^^^^^^^^^^^^
facturasieli  |   File "//.venv/lib/python3.11/site-packages/django/urls/resolvers.py", line 731, in urlconf_module
facturasieli  |     return import_module(self.urlconf_name)
facturasieli  |            ^^^^^^^^^^^^^^^^^^^^^^^^^^^^^^^^
facturasieli  |   File "/usr/lib/python3.11/importlib/__init__.py", line 126, in import_module
facturasieli  |     return _bootstrap._gcd_import(name[level:], package, level)
facturasieli  |            ^^^^^^^^^^^^^^^^^^^^^^^^^^^^^^^^^^^^^^^^^^^^^^^^^^^^
facturasieli  |   File "<frozen importlib._bootstrap>", line 1206, in _gcd_import
facturasieli  |   File "<frozen importlib._bootstrap>", line 1178, in _find_and_load
facturasieli  |   File "<frozen importlib._bootstrap>", line 1149, in _find_and_load_unlocked
facturasieli  |   File "<frozen importlib._bootstrap>", line 690, in _load_unlocked
facturasieli  |   File "<frozen importlib._bootstrap_external>", line 940, in exec_module
facturasieli  |   File "<frozen importlib._bootstrap>", line 241, in _call_with_frames_removed
facturasieli  |   File "/FacturaSieli/config/urls.py", line 34, in <module>
facturasieli  |     path('', include('facturasieli.urls')),
facturasieli  |              ^^^^^^^^^^^^^^^^^^^^^^^^^^^^
facturasieli  |   File "//.venv/lib/python3.11/site-packages/django/urls/conf.py", line 39, in include
facturasieli  |     urlconf_module = import_module(urlconf_module)
facturasieli  |                      ^^^^^^^^^^^^^^^^^^^^^^^^^^^^^
facturasieli  |   File "/usr/lib/python3.11/importlib/__init__.py", line 126, in import_module
facturasieli  |     return _bootstrap._gcd_import(name[level:], package, level)
facturasieli  |            ^^^^^^^^^^^^^^^^^^^^^^^^^^^^^^^^^^^^^^^^^^^^^^^^^^^^
facturasieli  |   File "<frozen importlib._bootstrap>", line 1206, in _gcd_import
facturasieli  |   File "<frozen importlib._bootstrap>", line 1178, in _find_and_load
facturasieli  |   File "<frozen importlib._bootstrap>", line 1149, in _find_and_load_unlocked
facturasieli  |   File "<frozen importlib._bootstrap>", line 690, in _load_unlocked
facturasieli  |   File "<frozen importlib._bootstrap_external>", line 940, in exec_module
facturasieli  |   File "<frozen importlib._bootstrap>", line 241, in _call_with_frames_removed
facturasieli  |   File "/FacturaSieli/facturasieli/urls.py", line 12, in <module>
facturasieli  |     from facturasieli.views.invoice_view import invoice_view, invoice_success
facturasieli  | ModuleNotFoundError: No module named 'facturasieli.views.invoice_view'
facturasieli  | /FacturaSieli/facturasieli/views/invoice/__init__.py changed, reloading.
facturasieli  | Performing system checks...
facturasieli  | 
facturasieli  | Watching for file changes with StatReloader
facturasieli  | Exception in thread django-main-thread:
facturasieli  | Traceback (most recent call last):
facturasieli  |   File "/usr/lib/python3.11/threading.py", line 1038, in _bootstrap_inner
facturasieli  |     self.run()
facturasieli  |   File "/usr/lib/python3.11/threading.py", line 975, in run
facturasieli  |     self._target(*self._args, **self._kwargs)
facturasieli  |   File "//.venv/lib/python3.11/site-packages/django/utils/autoreload.py", line 64, in wrapper
facturasieli  |     fn(*args, **kwargs)
facturasieli  |   File "//.venv/lib/python3.11/site-packages/django/core/management/commands/runserver.py", line 133, in inner_run
facturasieli  |     self.check(display_num_errors=True)
facturasieli  |   File "//.venv/lib/python3.11/site-packages/django/core/management/base.py", line 486, in check
facturasieli  |     all_issues = checks.run_checks(
facturasieli  |                  ^^^^^^^^^^^^^^^^^^
facturasieli  |   File "//.venv/lib/python3.11/site-packages/django/core/checks/registry.py", line 88, in run_checks
facturasieli  |     new_errors = check(app_configs=app_configs, databases=databases)
facturasieli  |                  ^^^^^^^^^^^^^^^^^^^^^^^^^^^^^^^^^^^^^^^^^^^^^^^^^^^
facturasieli  |   File "//.venv/lib/python3.11/site-packages/django/core/checks/urls.py", line 42, in check_url_namespaces_unique
facturasieli  |     all_namespaces = _load_all_namespaces(resolver)
facturasieli  |                      ^^^^^^^^^^^^^^^^^^^^^^^^^^^^^^
facturasieli  |   File "//.venv/lib/python3.11/site-packages/django/core/checks/urls.py", line 61, in _load_all_namespaces
facturasieli  |     url_patterns = getattr(resolver, "url_patterns", [])
facturasieli  |                    ^^^^^^^^^^^^^^^^^^^^^^^^^^^^^^^^^^^^^
facturasieli  |   File "//.venv/lib/python3.11/site-packages/django/utils/functional.py", line 47, in __get__
facturasieli  |     res = instance.__dict__[self.name] = self.func(instance)
facturasieli  |                                          ^^^^^^^^^^^^^^^^^^^
facturasieli  |   File "//.venv/lib/python3.11/site-packages/django/urls/resolvers.py", line 738, in url_patterns
facturasieli  |     patterns = getattr(self.urlconf_module, "urlpatterns", self.urlconf_module)
facturasieli  |                        ^^^^^^^^^^^^^^^^^^^
facturasieli  |   File "//.venv/lib/python3.11/site-packages/django/utils/functional.py", line 47, in __get__
facturasieli  |     res = instance.__dict__[self.name] = self.func(instance)
facturasieli  |                                          ^^^^^^^^^^^^^^^^^^^
facturasieli  |   File "//.venv/lib/python3.11/site-packages/django/urls/resolvers.py", line 731, in urlconf_module
facturasieli  |     return import_module(self.urlconf_name)
facturasieli  |            ^^^^^^^^^^^^^^^^^^^^^^^^^^^^^^^^
facturasieli  |   File "/usr/lib/python3.11/importlib/__init__.py", line 126, in import_module
facturasieli  |     return _bootstrap._gcd_import(name[level:], package, level)
facturasieli  |            ^^^^^^^^^^^^^^^^^^^^^^^^^^^^^^^^^^^^^^^^^^^^^^^^^^^^
facturasieli  |   File "<frozen importlib._bootstrap>", line 1206, in _gcd_import
facturasieli  |   File "<frozen importlib._bootstrap>", line 1178, in _find_and_load
facturasieli  |   File "<frozen importlib._bootstrap>", line 1149, in _find_and_load_unlocked
facturasieli  |   File "<frozen importlib._bootstrap>", line 690, in _load_unlocked
facturasieli  |   File "<frozen importlib._bootstrap_external>", line 940, in exec_module
facturasieli  |   File "<frozen importlib._bootstrap>", line 241, in _call_with_frames_removed
facturasieli  |   File "/FacturaSieli/config/urls.py", line 34, in <module>
facturasieli  |     path('', include('facturasieli.urls')),
facturasieli  |              ^^^^^^^^^^^^^^^^^^^^^^^^^^^^
facturasieli  |   File "//.venv/lib/python3.11/site-packages/django/urls/conf.py", line 39, in include
facturasieli  |     urlconf_module = import_module(urlconf_module)
facturasieli  |                      ^^^^^^^^^^^^^^^^^^^^^^^^^^^^^
facturasieli  |   File "/usr/lib/python3.11/importlib/__init__.py", line 126, in import_module
facturasieli  |     return _bootstrap._gcd_import(name[level:], package, level)
facturasieli  |            ^^^^^^^^^^^^^^^^^^^^^^^^^^^^^^^^^^^^^^^^^^^^^^^^^^^^
facturasieli  |   File "<frozen importlib._bootstrap>", line 1206, in _gcd_import
facturasieli  |   File "<frozen importlib._bootstrap>", line 1178, in _find_and_load
facturasieli  |   File "<frozen importlib._bootstrap>", line 1149, in _find_and_load_unlocked
facturasieli  |   File "<frozen importlib._bootstrap>", line 690, in _load_unlocked
facturasieli  |   File "<frozen importlib._bootstrap_external>", line 940, in exec_module
facturasieli  |   File "<frozen importlib._bootstrap>", line 241, in _call_with_frames_removed
facturasieli  |   File "/FacturaSieli/facturasieli/urls.py", line 11, in <module>
facturasieli  |     from facturasieli import views
facturasieli  |   File "/FacturaSieli/facturasieli/views/__init__.py", line 13, in <module>
facturasieli  |     from .invoice import * 
facturasieli  |     ^^^^^^^^^^^^^^^^^^^^^^
facturasieli  |   File "/FacturaSieli/facturasieli/views/invoice/__init__.py", line 9
facturasieli  |     __init__.py
facturasieli  | IndentationError: unexpected indent
facturasieli  | /FacturaSieli/facturasieli/views/invoice/__init__.py changed, reloading.
facturasieli  | Performing system checks...
facturasieli  | 
facturasieli  | Watching for file changes with StatReloader
facturasieli  | Exception in thread django-main-thread:
facturasieli  | Traceback (most recent call last):
facturasieli  |   File "/usr/lib/python3.11/threading.py", line 1038, in _bootstrap_inner
facturasieli  |     self.run()
facturasieli  |   File "/usr/lib/python3.11/threading.py", line 975, in run
facturasieli  |     self._target(*self._args, **self._kwargs)
facturasieli  |   File "//.venv/lib/python3.11/site-packages/django/utils/autoreload.py", line 64, in wrapper
facturasieli  |     fn(*args, **kwargs)
facturasieli  |   File "//.venv/lib/python3.11/site-packages/django/core/management/commands/runserver.py", line 133, in inner_run
facturasieli  |     self.check(display_num_errors=True)
facturasieli  |   File "//.venv/lib/python3.11/site-packages/django/core/management/base.py", line 486, in check
facturasieli  |     all_issues = checks.run_checks(
facturasieli  |                  ^^^^^^^^^^^^^^^^^^
facturasieli  |   File "//.venv/lib/python3.11/site-packages/django/core/checks/registry.py", line 88, in run_checks
facturasieli  |     new_errors = check(app_configs=app_configs, databases=databases)
facturasieli  |                  ^^^^^^^^^^^^^^^^^^^^^^^^^^^^^^^^^^^^^^^^^^^^^^^^^^^
facturasieli  |   File "//.venv/lib/python3.11/site-packages/django/core/checks/urls.py", line 42, in check_url_namespaces_unique
facturasieli  |     all_namespaces = _load_all_namespaces(resolver)
facturasieli  |                      ^^^^^^^^^^^^^^^^^^^^^^^^^^^^^^
facturasieli  |   File "//.venv/lib/python3.11/site-packages/django/core/checks/urls.py", line 61, in _load_all_namespaces
facturasieli  |     url_patterns = getattr(resolver, "url_patterns", [])
facturasieli  |                    ^^^^^^^^^^^^^^^^^^^^^^^^^^^^^^^^^^^^^
facturasieli  |   File "//.venv/lib/python3.11/site-packages/django/utils/functional.py", line 47, in __get__
facturasieli  |     res = instance.__dict__[self.name] = self.func(instance)
facturasieli  |                                          ^^^^^^^^^^^^^^^^^^^
facturasieli  |   File "//.venv/lib/python3.11/site-packages/django/urls/resolvers.py", line 738, in url_patterns
facturasieli  |     patterns = getattr(self.urlconf_module, "urlpatterns", self.urlconf_module)
facturasieli  |                        ^^^^^^^^^^^^^^^^^^^
facturasieli  |   File "//.venv/lib/python3.11/site-packages/django/utils/functional.py", line 47, in __get__
facturasieli  |     res = instance.__dict__[self.name] = self.func(instance)
facturasieli  |                                          ^^^^^^^^^^^^^^^^^^^
facturasieli  |   File "//.venv/lib/python3.11/site-packages/django/urls/resolvers.py", line 731, in urlconf_module
facturasieli  |     return import_module(self.urlconf_name)
facturasieli  |            ^^^^^^^^^^^^^^^^^^^^^^^^^^^^^^^^
facturasieli  |   File "/usr/lib/python3.11/importlib/__init__.py", line 126, in import_module
facturasieli  |     return _bootstrap._gcd_import(name[level:], package, level)
facturasieli  |            ^^^^^^^^^^^^^^^^^^^^^^^^^^^^^^^^^^^^^^^^^^^^^^^^^^^^
facturasieli  |   File "<frozen importlib._bootstrap>", line 1206, in _gcd_import
facturasieli  |   File "<frozen importlib._bootstrap>", line 1178, in _find_and_load
facturasieli  |   File "<frozen importlib._bootstrap>", line 1149, in _find_and_load_unlocked
facturasieli  |   File "<frozen importlib._bootstrap>", line 690, in _load_unlocked
facturasieli  |   File "<frozen importlib._bootstrap_external>", line 940, in exec_module
facturasieli  |   File "<frozen importlib._bootstrap>", line 241, in _call_with_frames_removed
facturasieli  |   File "/FacturaSieli/config/urls.py", line 34, in <module>
facturasieli  |     path('', include('facturasieli.urls')),
facturasieli  |              ^^^^^^^^^^^^^^^^^^^^^^^^^^^^
facturasieli  |   File "//.venv/lib/python3.11/site-packages/django/urls/conf.py", line 39, in include
facturasieli  |     urlconf_module = import_module(urlconf_module)
facturasieli  |                      ^^^^^^^^^^^^^^^^^^^^^^^^^^^^^
facturasieli  |   File "/usr/lib/python3.11/importlib/__init__.py", line 126, in import_module
facturasieli  |     return _bootstrap._gcd_import(name[level:], package, level)
facturasieli  |            ^^^^^^^^^^^^^^^^^^^^^^^^^^^^^^^^^^^^^^^^^^^^^^^^^^^^
facturasieli  |   File "<frozen importlib._bootstrap>", line 1206, in _gcd_import
facturasieli  |   File "<frozen importlib._bootstrap>", line 1178, in _find_and_load
facturasieli  |   File "<frozen importlib._bootstrap>", line 1149, in _find_and_load_unlocked
facturasieli  |   File "<frozen importlib._bootstrap>", line 690, in _load_unlocked
facturasieli  |   File "<frozen importlib._bootstrap_external>", line 940, in exec_module
facturasieli  |   File "<frozen importlib._bootstrap>", line 241, in _call_with_frames_removed
facturasieli  |   File "/FacturaSieli/facturasieli/urls.py", line 12, in <module>
facturasieli  |     from facturasieli.views.invoice_view import invoice_view, invoice_success
facturasieli  | ModuleNotFoundError: No module named 'facturasieli.views.invoice_view'
facturasieli  | /FacturaSieli/facturasieli/views/invoice/__init__.py changed, reloading.
facturasieli  | Performing system checks...
facturasieli  | 
facturasieli  | Watching for file changes with StatReloader
facturasieli  | Exception in thread django-main-thread:
facturasieli  | Traceback (most recent call last):
facturasieli  |   File "/usr/lib/python3.11/threading.py", line 1038, in _bootstrap_inner
facturasieli  |     self.run()
facturasieli  |   File "/usr/lib/python3.11/threading.py", line 975, in run
facturasieli  |     self._target(*self._args, **self._kwargs)
facturasieli  |   File "//.venv/lib/python3.11/site-packages/django/utils/autoreload.py", line 64, in wrapper
facturasieli  |     fn(*args, **kwargs)
facturasieli  |   File "//.venv/lib/python3.11/site-packages/django/core/management/commands/runserver.py", line 133, in inner_run
facturasieli  |     self.check(display_num_errors=True)
facturasieli  |   File "//.venv/lib/python3.11/site-packages/django/core/management/base.py", line 486, in check
facturasieli  |     all_issues = checks.run_checks(
facturasieli  |                  ^^^^^^^^^^^^^^^^^^
facturasieli  |   File "//.venv/lib/python3.11/site-packages/django/core/checks/registry.py", line 88, in run_checks
facturasieli  |     new_errors = check(app_configs=app_configs, databases=databases)
facturasieli  |                  ^^^^^^^^^^^^^^^^^^^^^^^^^^^^^^^^^^^^^^^^^^^^^^^^^^^
facturasieli  |   File "//.venv/lib/python3.11/site-packages/django/core/checks/urls.py", line 42, in check_url_namespaces_unique
facturasieli  |     all_namespaces = _load_all_namespaces(resolver)
facturasieli  |                      ^^^^^^^^^^^^^^^^^^^^^^^^^^^^^^
facturasieli  |   File "//.venv/lib/python3.11/site-packages/django/core/checks/urls.py", line 61, in _load_all_namespaces
facturasieli  |     url_patterns = getattr(resolver, "url_patterns", [])
facturasieli  |                    ^^^^^^^^^^^^^^^^^^^^^^^^^^^^^^^^^^^^^
facturasieli  |   File "//.venv/lib/python3.11/site-packages/django/utils/functional.py", line 47, in __get__
facturasieli  |     res = instance.__dict__[self.name] = self.func(instance)
facturasieli  |                                          ^^^^^^^^^^^^^^^^^^^
facturasieli  |   File "//.venv/lib/python3.11/site-packages/django/urls/resolvers.py", line 738, in url_patterns
facturasieli  |     patterns = getattr(self.urlconf_module, "urlpatterns", self.urlconf_module)
facturasieli  |                        ^^^^^^^^^^^^^^^^^^^
facturasieli  |   File "//.venv/lib/python3.11/site-packages/django/utils/functional.py", line 47, in __get__
facturasieli  |     res = instance.__dict__[self.name] = self.func(instance)
facturasieli  |                                          ^^^^^^^^^^^^^^^^^^^
facturasieli  |   File "//.venv/lib/python3.11/site-packages/django/urls/resolvers.py", line 731, in urlconf_module
facturasieli  |     return import_module(self.urlconf_name)
facturasieli  |            ^^^^^^^^^^^^^^^^^^^^^^^^^^^^^^^^
facturasieli  |   File "/usr/lib/python3.11/importlib/__init__.py", line 126, in import_module
facturasieli  |     return _bootstrap._gcd_import(name[level:], package, level)
facturasieli  |            ^^^^^^^^^^^^^^^^^^^^^^^^^^^^^^^^^^^^^^^^^^^^^^^^^^^^
facturasieli  |   File "<frozen importlib._bootstrap>", line 1206, in _gcd_import
facturasieli  |   File "<frozen importlib._bootstrap>", line 1178, in _find_and_load
facturasieli  |   File "<frozen importlib._bootstrap>", line 1149, in _find_and_load_unlocked
facturasieli  |   File "<frozen importlib._bootstrap>", line 690, in _load_unlocked
facturasieli  |   File "<frozen importlib._bootstrap_external>", line 940, in exec_module
facturasieli  |   File "<frozen importlib._bootstrap>", line 241, in _call_with_frames_removed
facturasieli  |   File "/FacturaSieli/config/urls.py", line 34, in <module>
facturasieli  |     path('', include('facturasieli.urls')),
facturasieli  |              ^^^^^^^^^^^^^^^^^^^^^^^^^^^^
facturasieli  |   File "//.venv/lib/python3.11/site-packages/django/urls/conf.py", line 39, in include
facturasieli  |     urlconf_module = import_module(urlconf_module)
facturasieli  |                      ^^^^^^^^^^^^^^^^^^^^^^^^^^^^^
facturasieli  |   File "/usr/lib/python3.11/importlib/__init__.py", line 126, in import_module
facturasieli  |     return _bootstrap._gcd_import(name[level:], package, level)
facturasieli  |            ^^^^^^^^^^^^^^^^^^^^^^^^^^^^^^^^^^^^^^^^^^^^^^^^^^^^
facturasieli  |   File "<frozen importlib._bootstrap>", line 1206, in _gcd_import
facturasieli  |   File "<frozen importlib._bootstrap>", line 1178, in _find_and_load
facturasieli  |   File "<frozen importlib._bootstrap>", line 1149, in _find_and_load_unlocked
facturasieli  |   File "<frozen importlib._bootstrap>", line 690, in _load_unlocked
facturasieli  |   File "<frozen importlib._bootstrap_external>", line 940, in exec_module
facturasieli  |   File "<frozen importlib._bootstrap>", line 241, in _call_with_frames_removed
facturasieli  |   File "/FacturaSieli/facturasieli/urls.py", line 12, in <module>
facturasieli  |     from facturasieli.views.invoice_view import invoice_view, invoice_success
facturasieli  | ModuleNotFoundError: No module named 'facturasieli.views.invoice_view'
facturasieli  | /FacturaSieli/facturasieli/views/invoice/__init__.py changed, reloading.
facturasieli  | Performing system checks...
facturasieli  | 
facturasieli  | Watching for file changes with StatReloader
facturasieli  | Exception in thread django-main-thread:
facturasieli  | Traceback (most recent call last):
facturasieli  |   File "/usr/lib/python3.11/threading.py", line 1038, in _bootstrap_inner
facturasieli  |     self.run()
facturasieli  |   File "/usr/lib/python3.11/threading.py", line 975, in run
facturasieli  |     self._target(*self._args, **self._kwargs)
facturasieli  |   File "//.venv/lib/python3.11/site-packages/django/utils/autoreload.py", line 64, in wrapper
facturasieli  |     fn(*args, **kwargs)
facturasieli  |   File "//.venv/lib/python3.11/site-packages/django/core/management/commands/runserver.py", line 133, in inner_run
facturasieli  |     self.check(display_num_errors=True)
facturasieli  |   File "//.venv/lib/python3.11/site-packages/django/core/management/base.py", line 486, in check
facturasieli  |     all_issues = checks.run_checks(
facturasieli  |                  ^^^^^^^^^^^^^^^^^^
facturasieli  |   File "//.venv/lib/python3.11/site-packages/django/core/checks/registry.py", line 88, in run_checks
facturasieli  |     new_errors = check(app_configs=app_configs, databases=databases)
facturasieli  |                  ^^^^^^^^^^^^^^^^^^^^^^^^^^^^^^^^^^^^^^^^^^^^^^^^^^^
facturasieli  |   File "//.venv/lib/python3.11/site-packages/django/core/checks/urls.py", line 42, in check_url_namespaces_unique
facturasieli  |     all_namespaces = _load_all_namespaces(resolver)
facturasieli  |                      ^^^^^^^^^^^^^^^^^^^^^^^^^^^^^^
facturasieli  |   File "//.venv/lib/python3.11/site-packages/django/core/checks/urls.py", line 61, in _load_all_namespaces
facturasieli  |     url_patterns = getattr(resolver, "url_patterns", [])
facturasieli  |                    ^^^^^^^^^^^^^^^^^^^^^^^^^^^^^^^^^^^^^
facturasieli  |   File "//.venv/lib/python3.11/site-packages/django/utils/functional.py", line 47, in __get__
facturasieli  |     res = instance.__dict__[self.name] = self.func(instance)
facturasieli  |                                          ^^^^^^^^^^^^^^^^^^^
facturasieli  |   File "//.venv/lib/python3.11/site-packages/django/urls/resolvers.py", line 738, in url_patterns
facturasieli  |     patterns = getattr(self.urlconf_module, "urlpatterns", self.urlconf_module)
facturasieli  |                        ^^^^^^^^^^^^^^^^^^^
facturasieli  |   File "//.venv/lib/python3.11/site-packages/django/utils/functional.py", line 47, in __get__
facturasieli  |     res = instance.__dict__[self.name] = self.func(instance)
facturasieli  |                                          ^^^^^^^^^^^^^^^^^^^
facturasieli  |   File "//.venv/lib/python3.11/site-packages/django/urls/resolvers.py", line 731, in urlconf_module
facturasieli  |     return import_module(self.urlconf_name)
facturasieli  |            ^^^^^^^^^^^^^^^^^^^^^^^^^^^^^^^^
facturasieli  |   File "/usr/lib/python3.11/importlib/__init__.py", line 126, in import_module
facturasieli  |     return _bootstrap._gcd_import(name[level:], package, level)
facturasieli  |            ^^^^^^^^^^^^^^^^^^^^^^^^^^^^^^^^^^^^^^^^^^^^^^^^^^^^
facturasieli  |   File "<frozen importlib._bootstrap>", line 1206, in _gcd_import
facturasieli  |   File "<frozen importlib._bootstrap>", line 1178, in _find_and_load
facturasieli  |   File "<frozen importlib._bootstrap>", line 1149, in _find_and_load_unlocked
facturasieli  |   File "<frozen importlib._bootstrap>", line 690, in _load_unlocked
facturasieli  |   File "<frozen importlib._bootstrap_external>", line 940, in exec_module
facturasieli  |   File "<frozen importlib._bootstrap>", line 241, in _call_with_frames_removed
facturasieli  |   File "/FacturaSieli/config/urls.py", line 34, in <module>
facturasieli  |     path('', include('facturasieli.urls')),
facturasieli  |              ^^^^^^^^^^^^^^^^^^^^^^^^^^^^
facturasieli  |   File "//.venv/lib/python3.11/site-packages/django/urls/conf.py", line 39, in include
facturasieli  |     urlconf_module = import_module(urlconf_module)
facturasieli  |                      ^^^^^^^^^^^^^^^^^^^^^^^^^^^^^
facturasieli  |   File "/usr/lib/python3.11/importlib/__init__.py", line 126, in import_module
facturasieli  |     return _bootstrap._gcd_import(name[level:], package, level)
facturasieli  |            ^^^^^^^^^^^^^^^^^^^^^^^^^^^^^^^^^^^^^^^^^^^^^^^^^^^^
facturasieli  |   File "<frozen importlib._bootstrap>", line 1206, in _gcd_import
facturasieli  |   File "<frozen importlib._bootstrap>", line 1178, in _find_and_load
facturasieli  |   File "<frozen importlib._bootstrap>", line 1149, in _find_and_load_unlocked
facturasieli  |   File "<frozen importlib._bootstrap>", line 690, in _load_unlocked
facturasieli  |   File "<frozen importlib._bootstrap_external>", line 940, in exec_module
facturasieli  |   File "<frozen importlib._bootstrap>", line 241, in _call_with_frames_removed
facturasieli  |   File "/FacturaSieli/facturasieli/urls.py", line 12, in <module>
facturasieli  |     from facturasieli.views.invoice_view import invoice_view, invoice_success
facturasieli  | ModuleNotFoundError: No module named 'facturasieli.views.invoice_view'
facturasieli  | Watching for file changes with StatReloader
facturasieli  | Exception in thread django-main-thread:
facturasieli  | Traceback (most recent call last):
facturasieli  |   File "/usr/lib/python3.11/threading.py", line 1038, in _bootstrap_inner
facturasieli  |     self.run()
facturasieli  |   File "/usr/lib/python3.11/threading.py", line 975, in run
facturasieli  |     self._target(*self._args, **self._kwargs)
facturasieli  |   File "//.venv/lib/python3.11/site-packages/django/utils/autoreload.py", line 64, in wrapper
facturasieli  |     fn(*args, **kwargs)
facturasieli  |   File "//.venv/lib/python3.11/site-packages/django/core/management/commands/runserver.py", line 133, in inner_run
facturasieli  |     self.check(display_num_errors=True)
facturasieli  |   File "//.venv/lib/python3.11/site-packages/django/core/management/base.py", line 486, in check
facturasieli  |     all_issues = checks.run_checks(
facturasieli  |                  ^^^^^^^^^^^^^^^^^^
facturasieli  |   File "//.venv/lib/python3.11/site-packages/django/core/checks/registry.py", line 88, in run_checks
facturasieli  |     new_errors = check(app_configs=app_configs, databases=databases)
facturasieli  |                  ^^^^^^^^^^^^^^^^^^^^^^^^^^^^^^^^^^^^^^^^^^^^^^^^^^^
facturasieli  |   File "//.venv/lib/python3.11/site-packages/django/core/checks/urls.py", line 42, in check_url_namespaces_unique
facturasieli  |     all_namespaces = _load_all_namespaces(resolver)
facturasieli  |                      ^^^^^^^^^^^^^^^^^^^^^^^^^^^^^^
facturasieli  |   File "//.venv/lib/python3.11/site-packages/django/core/checks/urls.py", line 61, in _load_all_namespaces
facturasieli  |     url_patterns = getattr(resolver, "url_patterns", [])
facturasieli  |                    ^^^^^^^^^^^^^^^^^^^^^^^^^^^^^^^^^^^^^
facturasieli  |   File "//.venv/lib/python3.11/site-packages/django/utils/functional.py", line 47, in __get__
facturasieli  |     res = instance.__dict__[self.name] = self.func(instance)
facturasieli  |                                          ^^^^^^^^^^^^^^^^^^^
facturasieli  |   File "//.venv/lib/python3.11/site-packages/django/urls/resolvers.py", line 738, in url_patterns
facturasieli  |     patterns = getattr(self.urlconf_module, "urlpatterns", self.urlconf_module)
facturasieli  |                        ^^^^^^^^^^^^^^^^^^^
facturasieli  |   File "//.venv/lib/python3.11/site-packages/django/utils/functional.py", line 47, in __get__
facturasieli  |     res = instance.__dict__[self.name] = self.func(instance)
facturasieli  |                                          ^^^^^^^^^^^^^^^^^^^
facturasieli  |   File "//.venv/lib/python3.11/site-packages/django/urls/resolvers.py", line 731, in urlconf_module
facturasieli  |     return import_module(self.urlconf_name)
facturasieli  |            ^^^^^^^^^^^^^^^^^^^^^^^^^^^^^^^^
facturasieli  |   File "/usr/lib/python3.11/importlib/__init__.py", line 126, in import_module
facturasieli  |     return _bootstrap._gcd_import(name[level:], package, level)
facturasieli  |            ^^^^^^^^^^^^^^^^^^^^^^^^^^^^^^^^^^^^^^^^^^^^^^^^^^^^
facturasieli  |   File "<frozen importlib._bootstrap>", line 1206, in _gcd_import
facturasieli  |   File "<frozen importlib._bootstrap>", line 1178, in _find_and_load
facturasieli  |   File "<frozen importlib._bootstrap>", line 1149, in _find_and_load_unlocked
facturasieli  |   File "<frozen importlib._bootstrap>", line 690, in _load_unlocked
facturasieli  |   File "<frozen importlib._bootstrap_external>", line 940, in exec_module
facturasieli  |   File "<frozen importlib._bootstrap>", line 241, in _call_with_frames_removed
facturasieli  |   File "/FacturaSieli/config/urls.py", line 34, in <module>
facturasieli  |     path('', include('facturasieli.urls')),
facturasieli  |              ^^^^^^^^^^^^^^^^^^^^^^^^^^^^
facturasieli  |   File "//.venv/lib/python3.11/site-packages/django/urls/conf.py", line 39, in include
facturasieli  |     urlconf_module = import_module(urlconf_module)
facturasieli  |                      ^^^^^^^^^^^^^^^^^^^^^^^^^^^^^
facturasieli  |   File "/usr/lib/python3.11/importlib/__init__.py", line 126, in import_module
facturasieli  |     return _bootstrap._gcd_import(name[level:], package, level)
facturasieli  |            ^^^^^^^^^^^^^^^^^^^^^^^^^^^^^^^^^^^^^^^^^^^^^^^^^^^^
facturasieli  |   File "<frozen importlib._bootstrap>", line 1206, in _gcd_import
facturasieli  |   File "<frozen importlib._bootstrap>", line 1178, in _find_and_load
facturasieli  |   File "<frozen importlib._bootstrap>", line 1149, in _find_and_load_unlocked
facturasieli  |   File "<frozen importlib._bootstrap>", line 690, in _load_unlocked
facturasieli  |   File "<frozen importlib._bootstrap_external>", line 940, in exec_module
facturasieli  |   File "<frozen importlib._bootstrap>", line 241, in _call_with_frames_removed
facturasieli  |   File "/FacturaSieli/facturasieli/urls.py", line 12, in <module>
facturasieli  |     from facturasieli.views.invoice_view import invoice_view, invoice_success
facturasieli  | ModuleNotFoundError: No module named 'facturasieli.views.invoice_view'
facturasieli  | /FacturaSieli/facturasieli/urls.py changed, reloading.
facturasieli  | Performing system checks...
facturasieli  | 
facturasieli  | Watching for file changes with StatReloader
facturasieli  | Watching for file changes with StatReloader
facturasieli  | [29/May/2024 14:35:24] "GET / HTTP/1.1" 302 0
facturasieli  | [29/May/2024 14:35:24] "GET /en/ HTTP/1.1" 200 4239
facturasieli  | [29/May/2024 14:35:24] "GET /media/default_avatar.jpg HTTP/1.1" 302 0
facturasieli  | [29/May/2024 14:35:25] "GET /en/media/default_avatar.jpg HTTP/1.1" 304 0
facturasieli  | [29/May/2024 14:36:06] "GET /invoice HTTP/1.1" 302 0
facturasieli  | [29/May/2024 14:36:06] "GET /en/invoice/ HTTP/1.1" 200 4808
facturasieli  | [29/May/2024 14:36:51] "POST /en/invoice/ HTTP/1.1" 200 5031
facturasieli  | [29/May/2024 14:47:48] "POST /en/invoice/ HTTP/1.1" 200 8510
facturasieli  | [29/May/2024 14:47:52] "POST /en/invoice/ HTTP/1.1" 200 8510
facturasieli  | [29/May/2024 14:59:47] "POST /en/invoice/ HTTP/1.1" 200 8510
facturasieli  | /FacturaSieli/facturasieli/views/invoice/invoice_view.py changed, reloading.
facturasieli  | Performing system checks...
facturasieli  | 
facturasieli  | System check identified no issues (0 silenced).
facturasieli  | May 29, 2024 - 14:35:01
facturasieli  | Django version 5.0.6, using settings 'config.settings'
facturasieli  | Starting development server at http://0.0.0.0:8000/
facturasieli  | Quit the server with CONTROL-C.
facturasieli  | 
facturasieli  | Watching for file changes with StatReloader
facturasieli  | /FacturaSieli/facturasieli/views/invoice/invoice_view.py changed, reloading.
facturasieli  | Performing system checks...
facturasieli  | 
facturasieli  | System check identified no issues (0 silenced).
facturasieli  | May 29, 2024 - 15:09:38
facturasieli  | Django version 5.0.6, using settings 'config.settings'
facturasieli  | Starting development server at http://0.0.0.0:8000/
facturasieli  | Quit the server with CONTROL-C.
facturasieli  | 
facturasieli  | Watching for file changes with StatReloader
facturasieli  | Watching for file changes with StatReloader
facturasieli  | Form is not valid: <ul class="errorlist"><li>status<ul class="errorlist"><li>Select a valid choice. 3 is not one of the available choices.</li></ul></li></ul>
facturasieli  | [29/May/2024 15:12:42] "POST /en/invoice/ HTTP/1.1" 200 8510
